[2021-May-10 13:43] 127.0.0.1 GET http /consulta/1234? 5xx INTERNAL SERVER ERROR
Traceback (most recent call last):
  File "/Users/rmj/webdev/BackEnd/flask_api_updown_auth/venv/lib/python3.7/site-packages/flask/app.py", line 1950, in full_dispatch_request
    rv = self.dispatch_request()
  File "/Users/rmj/webdev/BackEnd/flask_api_updown_auth/venv/lib/python3.7/site-packages/flask/app.py", line 1936, in dispatch_request
    return self.view_functions[rule.endpoint](**req.view_args)
  File "/Users/rmj/webdev/BackEnd/flask_api_updown_auth/apiupdown/__init__.py", line 97, in consulta_cartao
    resposta = str(db.query(Entrada).filter_by(cartao=cartao).first())
AttributeError: 'SQLAlchemy' object has no attribute 'query'

[2021-May-10 13:44] 127.0.0.1 GET http /consulta/1234? 5xx INTERNAL SERVER ERROR
Traceback (most recent call last):
  File "/Users/rmj/webdev/BackEnd/flask_api_updown_auth/venv/lib/python3.7/site-packages/flask/app.py", line 1950, in full_dispatch_request
    rv = self.dispatch_request()
  File "/Users/rmj/webdev/BackEnd/flask_api_updown_auth/venv/lib/python3.7/site-packages/flask/app.py", line 1936, in dispatch_request
    return self.view_functions[rule.endpoint](**req.view_args)
  File "/Users/rmj/webdev/BackEnd/flask_api_updown_auth/apiupdown/__init__.py", line 96, in consulta_cartao
    resposta = str(db.query(Entrada).filter_by(cartao=cartao).first())
AttributeError: 'SQLAlchemy' object has no attribute 'query'

[2021-May-10 13:44] 127.0.0.1 GET http /consulta/1234? 5xx INTERNAL SERVER ERROR
Traceback (most recent call last):
  File "/Users/rmj/webdev/BackEnd/flask_api_updown_auth/venv/lib/python3.7/site-packages/flask/app.py", line 1950, in full_dispatch_request
    rv = self.dispatch_request()
  File "/Users/rmj/webdev/BackEnd/flask_api_updown_auth/venv/lib/python3.7/site-packages/flask/app.py", line 1936, in dispatch_request
    return self.view_functions[rule.endpoint](**req.view_args)
  File "/Users/rmj/webdev/BackEnd/flask_api_updown_auth/apiupdown/__init__.py", line 96, in consulta_cartao
    resposta = db.query(Entrada).filter_by(cartao=cartao).first()
AttributeError: 'SQLAlchemy' object has no attribute 'query'

[2021-May-10 13:45] 127.0.0.1 POST http /insere_linha/C2     4456897999999999? 201 CREATED b'{\n  "msg": "Inserido: \'C\'-\'2\'-\'4456897999999999\'", \n  "success": true\n}\n'
[2021-May-10 13:45] 127.0.0.1 GET http /consulta/4456897999999999? 5xx INTERNAL SERVER ERROR
Traceback (most recent call last):
  File "/Users/rmj/webdev/BackEnd/flask_api_updown_auth/venv/lib/python3.7/site-packages/flask/app.py", line 1950, in full_dispatch_request
    rv = self.dispatch_request()
  File "/Users/rmj/webdev/BackEnd/flask_api_updown_auth/venv/lib/python3.7/site-packages/flask/app.py", line 1936, in dispatch_request
    return self.view_functions[rule.endpoint](**req.view_args)
  File "/Users/rmj/webdev/BackEnd/flask_api_updown_auth/apiupdown/__init__.py", line 96, in consulta_cartao
    resposta = db.query(Entrada).filter_by(cartao=cartao).first()
AttributeError: 'SQLAlchemy' object has no attribute 'query'

[2021-May-10 13:46] 127.0.0.1 GET http /consulta/4456897999999999? 201 CREATED b''
[2021-May-10 13:46] 127.0.0.1 GET http /consulta/4456897999999999? 201 CREATED b''
[2021-May-10 13:46] 127.0.0.1 GET http /consulta/4456897999999999? 201 CREATED b'4456897999999999'
[2021-May-10 13:46] 127.0.0.1 GET http /consulta/4456897999999999? 5xx INTERNAL SERVER ERROR
Traceback (most recent call last):
  File "/Users/rmj/webdev/BackEnd/flask_api_updown_auth/venv/lib/python3.7/site-packages/flask/app.py", line 1950, in full_dispatch_request
    rv = self.dispatch_request()
  File "/Users/rmj/webdev/BackEnd/flask_api_updown_auth/venv/lib/python3.7/site-packages/flask/app.py", line 1936, in dispatch_request
    return self.view_functions[rule.endpoint](**req.view_args)
  File "/Users/rmj/webdev/BackEnd/flask_api_updown_auth/apiupdown/__init__.py", line 97, in consulta_cartao
    return resposta._id, 201
AttributeError: 'Entrada' object has no attribute '_id'

[2021-May-10 13:47] 127.0.0.1 GET http /consulta/4456897999999999? 201 CREATED b'44'
[2021-May-10 13:48] 127.0.0.1 GET http /consulta/4456897999999999? 201 CREATED b'{\n  "id": "44", \n  "success": true\n}\n'
[2021-May-10 13:48] 127.0.0.1 GET http /consulta/44568979999? 5xx INTERNAL SERVER ERROR
Traceback (most recent call last):
  File "/Users/rmj/webdev/BackEnd/flask_api_updown_auth/venv/lib/python3.7/site-packages/flask/app.py", line 1950, in full_dispatch_request
    rv = self.dispatch_request()
  File "/Users/rmj/webdev/BackEnd/flask_api_updown_auth/venv/lib/python3.7/site-packages/flask/app.py", line 1936, in dispatch_request
    return self.view_functions[rule.endpoint](**req.view_args)
  File "/Users/rmj/webdev/BackEnd/flask_api_updown_auth/apiupdown/__init__.py", line 98, in consulta_cartao
    'id' : str(resposta.id),
AttributeError: 'NoneType' object has no attribute 'id'

[2021-May-10 13:51] 127.0.0.1 GET http /consulta/4456897999999999? 201 CREATED b'{\n  "id": "44", \n  "success": true\n}\n'
[2021-May-10 13:51] 127.0.0.1 GET http /consulta/445689799999999? 400 BAD REQUEST b'{\n  "msg": "Cart\\u00e3o n\\u00e3o encontrado na base", \n  "success": false\n}\n'
[2021-May-10 13:52] 127.0.0.1 GET http /consulta/445689799999999? 400 BAD REQUEST b'{\n  "msg": "Cartao nao encontrado na base", \n  "success": false\n}\n'
[2021-May-10 14:04] 127.0.0.1 GET http /consulta/445689799999999? 400 BAD REQUEST b'{\n  "msg": "Cartao nao encontrado na base", \n  "success": false\n}\n'
[2021-May-10 14:05] 127.0.0.1 GET http /consulta/445689799999999? 400 BAD REQUEST b'{\n  "msg": "Cartao nao encontrado na base", \n  "success": false\n}\n'
[10-May-2021 14:06] 127.0.0.1 GET http /consulta/445689799999999? 400 BAD REQUEST b'{\n  "msg": "Cartao nao encontrado na base", \n  "success": false\n}\n'
[10-May-2021 14:06] 127.0.0.1 GET http /consulta/445689799999999? 400 BAD REQUEST b'{\n  "msg": "Cartao nao encontrado na base", \n  "success": false\n}\n'
[10-May-2021 14:06] 127.0.0.1 GET http /consulta/4456897999999999? 201 CREATED b'{\n  "id": "44", \n  "success": true\n}\n'
[10-May-2021 14:06] 127.0.0.1 GET http /consulta/4456897999999999? 200 OK b'{\n  "id": "44", \n  "success": true\n}\n'
[10-May-2021 14:09] 127.0.0.1 GET http /consulta/4456897999999999? 200 OK b'{\n  "id": "44", \n  "success": true\n}\n'
[10-May-2021 14:09] 127.0.0.1 GET http /consulta/445689799999999? 400 BAD REQUEST b'{\n  "msg": "Cartao nao encontrado na base", \n  "success": false\n}\n'
[10-May-2021 14:51] 127.0.0.1 POST http /insere_arquivo/? 5xx INTERNAL SERVER ERROR
Traceback (most recent call last):
  File "/Users/rmj/webdev/BackEnd/flask_api_updown_auth/venv/lib/python3.7/site-packages/flask/app.py", line 1950, in full_dispatch_request
    rv = self.dispatch_request()
  File "/Users/rmj/webdev/BackEnd/flask_api_updown_auth/venv/lib/python3.7/site-packages/flask/app.py", line 1926, in dispatch_request
    self.raise_routing_exception(req)
  File "/Users/rmj/webdev/BackEnd/flask_api_updown_auth/venv/lib/python3.7/site-packages/flask/app.py", line 1908, in raise_routing_exception
    raise request.routing_exception
  File "/Users/rmj/webdev/BackEnd/flask_api_updown_auth/venv/lib/python3.7/site-packages/flask/ctx.py", line 350, in match_request
    result = self.url_adapter.match(return_rule=True)
  File "/Users/rmj/webdev/BackEnd/flask_api_updown_auth/venv/lib/python3.7/site-packages/werkzeug/routing.py", line 1945, in match
    raise NotFound()
werkzeug.exceptions.NotFound: 404 Not Found: The requested URL was not found on the server. If you entered the URL manually please check your spelling and try again.

[10-May-2021 14:51] 127.0.0.1 POST http /insere_arquivo/? 5xx INTERNAL SERVER ERROR
Traceback (most recent call last):
  File "/Users/rmj/webdev/BackEnd/flask_api_updown_auth/venv/lib/python3.7/site-packages/flask/app.py", line 1950, in full_dispatch_request
    rv = self.dispatch_request()
  File "/Users/rmj/webdev/BackEnd/flask_api_updown_auth/venv/lib/python3.7/site-packages/flask/app.py", line 1926, in dispatch_request
    self.raise_routing_exception(req)
  File "/Users/rmj/webdev/BackEnd/flask_api_updown_auth/venv/lib/python3.7/site-packages/flask/app.py", line 1908, in raise_routing_exception
    raise request.routing_exception
  File "/Users/rmj/webdev/BackEnd/flask_api_updown_auth/venv/lib/python3.7/site-packages/flask/ctx.py", line 350, in match_request
    result = self.url_adapter.match(return_rule=True)
  File "/Users/rmj/webdev/BackEnd/flask_api_updown_auth/venv/lib/python3.7/site-packages/werkzeug/routing.py", line 1945, in match
    raise NotFound()
werkzeug.exceptions.NotFound: 404 Not Found: The requested URL was not found on the server. If you entered the URL manually please check your spelling and try again.

[10-May-2021 14:51] 127.0.0.1 POST http /insere_arquivo/? 5xx INTERNAL SERVER ERROR
Traceback (most recent call last):
  File "/Users/rmj/webdev/BackEnd/flask_api_updown_auth/venv/lib/python3.7/site-packages/flask/app.py", line 1950, in full_dispatch_request
    rv = self.dispatch_request()
  File "/Users/rmj/webdev/BackEnd/flask_api_updown_auth/venv/lib/python3.7/site-packages/flask/app.py", line 1926, in dispatch_request
    self.raise_routing_exception(req)
  File "/Users/rmj/webdev/BackEnd/flask_api_updown_auth/venv/lib/python3.7/site-packages/flask/app.py", line 1908, in raise_routing_exception
    raise request.routing_exception
  File "/Users/rmj/webdev/BackEnd/flask_api_updown_auth/venv/lib/python3.7/site-packages/flask/ctx.py", line 350, in match_request
    result = self.url_adapter.match(return_rule=True)
  File "/Users/rmj/webdev/BackEnd/flask_api_updown_auth/venv/lib/python3.7/site-packages/werkzeug/routing.py", line 1945, in match
    raise NotFound()
werkzeug.exceptions.NotFound: 404 Not Found: The requested URL was not found on the server. If you entered the URL manually please check your spelling and try again.

[10-May-2021 14:51] 127.0.0.1 POST http /insere_arquivo/? 5xx INTERNAL SERVER ERROR
Traceback (most recent call last):
  File "/Users/rmj/webdev/BackEnd/flask_api_updown_auth/venv/lib/python3.7/site-packages/flask/app.py", line 1950, in full_dispatch_request
    rv = self.dispatch_request()
  File "/Users/rmj/webdev/BackEnd/flask_api_updown_auth/venv/lib/python3.7/site-packages/flask/app.py", line 1926, in dispatch_request
    self.raise_routing_exception(req)
  File "/Users/rmj/webdev/BackEnd/flask_api_updown_auth/venv/lib/python3.7/site-packages/flask/app.py", line 1908, in raise_routing_exception
    raise request.routing_exception
  File "/Users/rmj/webdev/BackEnd/flask_api_updown_auth/venv/lib/python3.7/site-packages/flask/ctx.py", line 350, in match_request
    result = self.url_adapter.match(return_rule=True)
  File "/Users/rmj/webdev/BackEnd/flask_api_updown_auth/venv/lib/python3.7/site-packages/werkzeug/routing.py", line 1945, in match
    raise NotFound()
werkzeug.exceptions.NotFound: 404 Not Found: The requested URL was not found on the server. If you entered the URL manually please check your spelling and try again.

[10-May-2021 14:51] 127.0.0.1 POST http /insere_arquivo/? 404 NOT FOUND b'<!DOCTYPE HTML PUBLIC "-//W3C//DTD HTML 3.2 Final//EN">\n<title>404 Not Found</title>\n<h1>Not Found</h1>\n<p>The requested URL was not found on the server. If you entered the URL manually please check your spelling and try again.</p>\n'
[10-May-2021 14:51] 127.0.0.1 POST http /insere_arquivo/? 404 NOT FOUND b'<!DOCTYPE HTML PUBLIC "-//W3C//DTD HTML 3.2 Final//EN">\n<title>404 Not Found</title>\n<h1>Not Found</h1>\n<p>The requested URL was not found on the server. If you entered the URL manually please check your spelling and try again.</p>\n'
[10-May-2021 14:51] 127.0.0.1 POST http /insere_arquivo/? 404 NOT FOUND b'<!DOCTYPE HTML PUBLIC "-//W3C//DTD HTML 3.2 Final//EN">\n<title>404 Not Found</title>\n<h1>Not Found</h1>\n<p>The requested URL was not found on the server. If you entered the URL manually please check your spelling and try again.</p>\n'
[10-May-2021 14:51] 127.0.0.1 POST http /insere_arquivo/? 404 NOT FOUND b'<!DOCTYPE HTML PUBLIC "-//W3C//DTD HTML 3.2 Final//EN">\n<title>404 Not Found</title>\n<h1>Not Found</h1>\n<p>The requested URL was not found on the server. If you entered the URL manually please check your spelling and try again.</p>\n'
[10-May-2021 14:52] 127.0.0.1 POST http /insere_arquivo/? 5xx INTERNAL SERVER ERROR
Traceback (most recent call last):
  File "/Users/rmj/webdev/BackEnd/flask_api_updown_auth/venv/lib/python3.7/site-packages/flask/app.py", line 1950, in full_dispatch_request
    rv = self.dispatch_request()
  File "/Users/rmj/webdev/BackEnd/flask_api_updown_auth/venv/lib/python3.7/site-packages/flask/app.py", line 1926, in dispatch_request
    self.raise_routing_exception(req)
  File "/Users/rmj/webdev/BackEnd/flask_api_updown_auth/venv/lib/python3.7/site-packages/flask/app.py", line 1908, in raise_routing_exception
    raise request.routing_exception
  File "/Users/rmj/webdev/BackEnd/flask_api_updown_auth/venv/lib/python3.7/site-packages/flask/ctx.py", line 350, in match_request
    result = self.url_adapter.match(return_rule=True)
  File "/Users/rmj/webdev/BackEnd/flask_api_updown_auth/venv/lib/python3.7/site-packages/werkzeug/routing.py", line 1945, in match
    raise NotFound()
werkzeug.exceptions.NotFound: 404 Not Found: The requested URL was not found on the server. If you entered the URL manually please check your spelling and try again.

[10-May-2021 14:52] 127.0.0.1 POST http /insere_arquivo/? 404 NOT FOUND b'<!DOCTYPE HTML PUBLIC "-//W3C//DTD HTML 3.2 Final//EN">\n<title>404 Not Found</title>\n<h1>Not Found</h1>\n<p>The requested URL was not found on the server. If you entered the URL manually please check your spelling and try again.</p>\n'
[10-May-2021 14:53] 127.0.0.1 POST http /insere_arquivo/? 5xx INTERNAL SERVER ERROR
Traceback (most recent call last):
  File "/Users/rmj/webdev/BackEnd/flask_api_updown_auth/venv/lib/python3.7/site-packages/flask/app.py", line 1950, in full_dispatch_request
    rv = self.dispatch_request()
  File "/Users/rmj/webdev/BackEnd/flask_api_updown_auth/venv/lib/python3.7/site-packages/flask/app.py", line 1926, in dispatch_request
    self.raise_routing_exception(req)
  File "/Users/rmj/webdev/BackEnd/flask_api_updown_auth/venv/lib/python3.7/site-packages/flask/app.py", line 1908, in raise_routing_exception
    raise request.routing_exception
  File "/Users/rmj/webdev/BackEnd/flask_api_updown_auth/venv/lib/python3.7/site-packages/flask/ctx.py", line 350, in match_request
    result = self.url_adapter.match(return_rule=True)
  File "/Users/rmj/webdev/BackEnd/flask_api_updown_auth/venv/lib/python3.7/site-packages/werkzeug/routing.py", line 1945, in match
    raise NotFound()
werkzeug.exceptions.NotFound: 404 Not Found: The requested URL was not found on the server. If you entered the URL manually please check your spelling and try again.

[10-May-2021 14:53] 127.0.0.1 POST http /insere_arquivo/? 404 NOT FOUND b'<!DOCTYPE HTML PUBLIC "-//W3C//DTD HTML 3.2 Final//EN">\n<title>404 Not Found</title>\n<h1>Not Found</h1>\n<p>The requested URL was not found on the server. If you entered the URL manually please check your spelling and try again.</p>\n'
[10-May-2021 14:53] 127.0.0.1 POST http /insere_arquivo/? 5xx INTERNAL SERVER ERROR
Traceback (most recent call last):
  File "/Users/rmj/webdev/BackEnd/flask_api_updown_auth/venv/lib/python3.7/site-packages/flask/app.py", line 1950, in full_dispatch_request
    rv = self.dispatch_request()
  File "/Users/rmj/webdev/BackEnd/flask_api_updown_auth/venv/lib/python3.7/site-packages/flask/app.py", line 1926, in dispatch_request
    self.raise_routing_exception(req)
  File "/Users/rmj/webdev/BackEnd/flask_api_updown_auth/venv/lib/python3.7/site-packages/flask/app.py", line 1908, in raise_routing_exception
    raise request.routing_exception
  File "/Users/rmj/webdev/BackEnd/flask_api_updown_auth/venv/lib/python3.7/site-packages/flask/ctx.py", line 350, in match_request
    result = self.url_adapter.match(return_rule=True)
  File "/Users/rmj/webdev/BackEnd/flask_api_updown_auth/venv/lib/python3.7/site-packages/werkzeug/routing.py", line 1945, in match
    raise NotFound()
werkzeug.exceptions.NotFound: 404 Not Found: The requested URL was not found on the server. If you entered the URL manually please check your spelling and try again.

[10-May-2021 14:53] 127.0.0.1 POST http /insere_arquivo/? 404 NOT FOUND b'<!DOCTYPE HTML PUBLIC "-//W3C//DTD HTML 3.2 Final//EN">\n<title>404 Not Found</title>\n<h1>Not Found</h1>\n<p>The requested URL was not found on the server. If you entered the URL manually please check your spelling and try again.</p>\n'
[10-May-2021 14:54] 127.0.0.1 POST http /insere_arquivo/? 5xx INTERNAL SERVER ERROR
Traceback (most recent call last):
  File "/Users/rmj/webdev/BackEnd/flask_api_updown_auth/venv/lib/python3.7/site-packages/flask/app.py", line 1950, in full_dispatch_request
    rv = self.dispatch_request()
  File "/Users/rmj/webdev/BackEnd/flask_api_updown_auth/venv/lib/python3.7/site-packages/flask/app.py", line 1926, in dispatch_request
    self.raise_routing_exception(req)
  File "/Users/rmj/webdev/BackEnd/flask_api_updown_auth/venv/lib/python3.7/site-packages/flask/app.py", line 1908, in raise_routing_exception
    raise request.routing_exception
  File "/Users/rmj/webdev/BackEnd/flask_api_updown_auth/venv/lib/python3.7/site-packages/flask/ctx.py", line 350, in match_request
    result = self.url_adapter.match(return_rule=True)
  File "/Users/rmj/webdev/BackEnd/flask_api_updown_auth/venv/lib/python3.7/site-packages/werkzeug/routing.py", line 1945, in match
    raise NotFound()
werkzeug.exceptions.NotFound: 404 Not Found: The requested URL was not found on the server. If you entered the URL manually please check your spelling and try again.

[10-May-2021 14:54] 127.0.0.1 POST http /insere_arquivo/? 404 NOT FOUND b'<!DOCTYPE HTML PUBLIC "-//W3C//DTD HTML 3.2 Final//EN">\n<title>404 Not Found</title>\n<h1>Not Found</h1>\n<p>The requested URL was not found on the server. If you entered the URL manually please check your spelling and try again.</p>\n'
[10-May-2021 14:54] 127.0.0.1 POST http /insere_arquivo/? 5xx INTERNAL SERVER ERROR
Traceback (most recent call last):
  File "/Users/rmj/webdev/BackEnd/flask_api_updown_auth/venv/lib/python3.7/site-packages/flask/app.py", line 1950, in full_dispatch_request
    rv = self.dispatch_request()
  File "/Users/rmj/webdev/BackEnd/flask_api_updown_auth/venv/lib/python3.7/site-packages/flask/app.py", line 1926, in dispatch_request
    self.raise_routing_exception(req)
  File "/Users/rmj/webdev/BackEnd/flask_api_updown_auth/venv/lib/python3.7/site-packages/flask/app.py", line 1908, in raise_routing_exception
    raise request.routing_exception
  File "/Users/rmj/webdev/BackEnd/flask_api_updown_auth/venv/lib/python3.7/site-packages/flask/ctx.py", line 350, in match_request
    result = self.url_adapter.match(return_rule=True)
  File "/Users/rmj/webdev/BackEnd/flask_api_updown_auth/venv/lib/python3.7/site-packages/werkzeug/routing.py", line 1945, in match
    raise NotFound()
werkzeug.exceptions.NotFound: 404 Not Found: The requested URL was not found on the server. If you entered the URL manually please check your spelling and try again.

[10-May-2021 14:54] 127.0.0.1 POST http /insere_arquivo/? 404 NOT FOUND b'<!DOCTYPE HTML PUBLIC "-//W3C//DTD HTML 3.2 Final//EN">\n<title>404 Not Found</title>\n<h1>Not Found</h1>\n<p>The requested URL was not found on the server. If you entered the URL manually please check your spelling and try again.</p>\n'
[10-May-2021 14:55] 127.0.0.1 POST http /insere_arquivo/? 5xx INTERNAL SERVER ERROR
Traceback (most recent call last):
  File "/Users/rmj/webdev/BackEnd/flask_api_updown_auth/venv/lib/python3.7/site-packages/flask/app.py", line 1950, in full_dispatch_request
    rv = self.dispatch_request()
  File "/Users/rmj/webdev/BackEnd/flask_api_updown_auth/venv/lib/python3.7/site-packages/flask/app.py", line 1926, in dispatch_request
    self.raise_routing_exception(req)
  File "/Users/rmj/webdev/BackEnd/flask_api_updown_auth/venv/lib/python3.7/site-packages/flask/app.py", line 1908, in raise_routing_exception
    raise request.routing_exception
  File "/Users/rmj/webdev/BackEnd/flask_api_updown_auth/venv/lib/python3.7/site-packages/flask/ctx.py", line 350, in match_request
    result = self.url_adapter.match(return_rule=True)
  File "/Users/rmj/webdev/BackEnd/flask_api_updown_auth/venv/lib/python3.7/site-packages/werkzeug/routing.py", line 1945, in match
    raise NotFound()
werkzeug.exceptions.NotFound: 404 Not Found: The requested URL was not found on the server. If you entered the URL manually please check your spelling and try again.

[10-May-2021 14:55] 127.0.0.1 POST http /insere_arquivo/? 404 NOT FOUND b'<!DOCTYPE HTML PUBLIC "-//W3C//DTD HTML 3.2 Final//EN">\n<title>404 Not Found</title>\n<h1>Not Found</h1>\n<p>The requested URL was not found on the server. If you entered the URL manually please check your spelling and try again.</p>\n'
[10-May-2021 14:57] 127.0.0.1 POST http /insere_arquivo/? 5xx INTERNAL SERVER ERROR
Traceback (most recent call last):
  File "/Users/rmj/webdev/BackEnd/flask_api_updown_auth/venv/lib/python3.7/site-packages/flask/app.py", line 1950, in full_dispatch_request
    rv = self.dispatch_request()
  File "/Users/rmj/webdev/BackEnd/flask_api_updown_auth/venv/lib/python3.7/site-packages/flask/app.py", line 1926, in dispatch_request
    self.raise_routing_exception(req)
  File "/Users/rmj/webdev/BackEnd/flask_api_updown_auth/venv/lib/python3.7/site-packages/flask/app.py", line 1908, in raise_routing_exception
    raise request.routing_exception
  File "/Users/rmj/webdev/BackEnd/flask_api_updown_auth/venv/lib/python3.7/site-packages/flask/ctx.py", line 350, in match_request
    result = self.url_adapter.match(return_rule=True)
  File "/Users/rmj/webdev/BackEnd/flask_api_updown_auth/venv/lib/python3.7/site-packages/werkzeug/routing.py", line 1945, in match
    raise NotFound()
werkzeug.exceptions.NotFound: 404 Not Found: The requested URL was not found on the server. If you entered the URL manually please check your spelling and try again.

[10-May-2021 14:57] 127.0.0.1 POST http /insere_arquivo/? 404 NOT FOUND b'<!DOCTYPE HTML PUBLIC "-//W3C//DTD HTML 3.2 Final//EN">\n<title>404 Not Found</title>\n<h1>Not Found</h1>\n<p>The requested URL was not found on the server. If you entered the URL manually please check your spelling and try again.</p>\n'
[10-May-2021 14:57] 127.0.0.1 POST http /insere_arquivo/? 5xx INTERNAL SERVER ERROR
Traceback (most recent call last):
  File "/Users/rmj/webdev/BackEnd/flask_api_updown_auth/venv/lib/python3.7/site-packages/flask/app.py", line 1950, in full_dispatch_request
    rv = self.dispatch_request()
  File "/Users/rmj/webdev/BackEnd/flask_api_updown_auth/venv/lib/python3.7/site-packages/flask/app.py", line 1926, in dispatch_request
    self.raise_routing_exception(req)
  File "/Users/rmj/webdev/BackEnd/flask_api_updown_auth/venv/lib/python3.7/site-packages/flask/app.py", line 1908, in raise_routing_exception
    raise request.routing_exception
  File "/Users/rmj/webdev/BackEnd/flask_api_updown_auth/venv/lib/python3.7/site-packages/flask/ctx.py", line 350, in match_request
    result = self.url_adapter.match(return_rule=True)
  File "/Users/rmj/webdev/BackEnd/flask_api_updown_auth/venv/lib/python3.7/site-packages/werkzeug/routing.py", line 1945, in match
    raise NotFound()
werkzeug.exceptions.NotFound: 404 Not Found: The requested URL was not found on the server. If you entered the URL manually please check your spelling and try again.

[10-May-2021 14:57] 127.0.0.1 POST http /insere_arquivo/? 404 NOT FOUND b'<!DOCTYPE HTML PUBLIC "-//W3C//DTD HTML 3.2 Final//EN">\n<title>404 Not Found</title>\n<h1>Not Found</h1>\n<p>The requested URL was not found on the server. If you entered the URL manually please check your spelling and try again.</p>\n'
[10-May-2021 14:58] 127.0.0.1 POST http /insere_arquivo/? 5xx INTERNAL SERVER ERROR
Traceback (most recent call last):
  File "/Users/rmj/webdev/BackEnd/flask_api_updown_auth/venv/lib/python3.7/site-packages/flask/app.py", line 1950, in full_dispatch_request
    rv = self.dispatch_request()
  File "/Users/rmj/webdev/BackEnd/flask_api_updown_auth/venv/lib/python3.7/site-packages/flask/app.py", line 1926, in dispatch_request
    self.raise_routing_exception(req)
  File "/Users/rmj/webdev/BackEnd/flask_api_updown_auth/venv/lib/python3.7/site-packages/flask/app.py", line 1908, in raise_routing_exception
    raise request.routing_exception
  File "/Users/rmj/webdev/BackEnd/flask_api_updown_auth/venv/lib/python3.7/site-packages/flask/ctx.py", line 350, in match_request
    result = self.url_adapter.match(return_rule=True)
  File "/Users/rmj/webdev/BackEnd/flask_api_updown_auth/venv/lib/python3.7/site-packages/werkzeug/routing.py", line 1945, in match
    raise NotFound()
werkzeug.exceptions.NotFound: 404 Not Found: The requested URL was not found on the server. If you entered the URL manually please check your spelling and try again.

[10-May-2021 14:58] 127.0.0.1 POST http /insere_arquivo/? 404 NOT FOUND b'<!DOCTYPE HTML PUBLIC "-//W3C//DTD HTML 3.2 Final//EN">\n<title>404 Not Found</title>\n<h1>Not Found</h1>\n<p>The requested URL was not found on the server. If you entered the URL manually please check your spelling and try again.</p>\n'
[10-May-2021 14:59] 127.0.0.1 POST http /insere/? 5xx INTERNAL SERVER ERROR
Traceback (most recent call last):
  File "/Users/rmj/webdev/BackEnd/flask_api_updown_auth/venv/lib/python3.7/site-packages/flask/app.py", line 1950, in full_dispatch_request
    rv = self.dispatch_request()
  File "/Users/rmj/webdev/BackEnd/flask_api_updown_auth/venv/lib/python3.7/site-packages/flask/app.py", line 1926, in dispatch_request
    self.raise_routing_exception(req)
  File "/Users/rmj/webdev/BackEnd/flask_api_updown_auth/venv/lib/python3.7/site-packages/flask/app.py", line 1908, in raise_routing_exception
    raise request.routing_exception
  File "/Users/rmj/webdev/BackEnd/flask_api_updown_auth/venv/lib/python3.7/site-packages/flask/ctx.py", line 350, in match_request
    result = self.url_adapter.match(return_rule=True)
  File "/Users/rmj/webdev/BackEnd/flask_api_updown_auth/venv/lib/python3.7/site-packages/werkzeug/routing.py", line 1945, in match
    raise NotFound()
werkzeug.exceptions.NotFound: 404 Not Found: The requested URL was not found on the server. If you entered the URL manually please check your spelling and try again.

[10-May-2021 14:59] 127.0.0.1 POST http /insere/? 404 NOT FOUND b'<!DOCTYPE HTML PUBLIC "-//W3C//DTD HTML 3.2 Final//EN">\n<title>404 Not Found</title>\n<h1>Not Found</h1>\n<p>The requested URL was not found on the server. If you entered the URL manually please check your spelling and try again.</p>\n'
[10-May-2021 14:59] 127.0.0.1 POST http /insere/coiso.txt? 201 CREATED b''
[10-May-2021 15:00] 127.0.0.1 POST http /insere/? 5xx INTERNAL SERVER ERROR
Traceback (most recent call last):
  File "/Users/rmj/webdev/BackEnd/flask_api_updown_auth/venv/lib/python3.7/site-packages/flask/app.py", line 1950, in full_dispatch_request
    rv = self.dispatch_request()
  File "/Users/rmj/webdev/BackEnd/flask_api_updown_auth/venv/lib/python3.7/site-packages/flask/app.py", line 1926, in dispatch_request
    self.raise_routing_exception(req)
  File "/Users/rmj/webdev/BackEnd/flask_api_updown_auth/venv/lib/python3.7/site-packages/flask/app.py", line 1908, in raise_routing_exception
    raise request.routing_exception
  File "/Users/rmj/webdev/BackEnd/flask_api_updown_auth/venv/lib/python3.7/site-packages/flask/ctx.py", line 350, in match_request
    result = self.url_adapter.match(return_rule=True)
  File "/Users/rmj/webdev/BackEnd/flask_api_updown_auth/venv/lib/python3.7/site-packages/werkzeug/routing.py", line 1945, in match
    raise NotFound()
werkzeug.exceptions.NotFound: 404 Not Found: The requested URL was not found on the server. If you entered the URL manually please check your spelling and try again.

[10-May-2021 15:00] 127.0.0.1 POST http /insere/? 404 NOT FOUND b'<!DOCTYPE HTML PUBLIC "-//W3C//DTD HTML 3.2 Final//EN">\n<title>404 Not Found</title>\n<h1>Not Found</h1>\n<p>The requested URL was not found on the server. If you entered the URL manually please check your spelling and try again.</p>\n'
[10-May-2021 15:00] 127.0.0.1 POST http /insere/? 5xx INTERNAL SERVER ERROR
Traceback (most recent call last):
  File "/Users/rmj/webdev/BackEnd/flask_api_updown_auth/venv/lib/python3.7/site-packages/flask/app.py", line 1950, in full_dispatch_request
    rv = self.dispatch_request()
  File "/Users/rmj/webdev/BackEnd/flask_api_updown_auth/venv/lib/python3.7/site-packages/flask/app.py", line 1926, in dispatch_request
    self.raise_routing_exception(req)
  File "/Users/rmj/webdev/BackEnd/flask_api_updown_auth/venv/lib/python3.7/site-packages/flask/app.py", line 1908, in raise_routing_exception
    raise request.routing_exception
  File "/Users/rmj/webdev/BackEnd/flask_api_updown_auth/venv/lib/python3.7/site-packages/flask/ctx.py", line 350, in match_request
    result = self.url_adapter.match(return_rule=True)
  File "/Users/rmj/webdev/BackEnd/flask_api_updown_auth/venv/lib/python3.7/site-packages/werkzeug/routing.py", line 1945, in match
    raise NotFound()
werkzeug.exceptions.NotFound: 404 Not Found: The requested URL was not found on the server. If you entered the URL manually please check your spelling and try again.

[10-May-2021 15:00] 127.0.0.1 POST http /insere/? 404 NOT FOUND b'<!DOCTYPE HTML PUBLIC "-//W3C//DTD HTML 3.2 Final//EN">\n<title>404 Not Found</title>\n<h1>Not Found</h1>\n<p>The requested URL was not found on the server. If you entered the URL manually please check your spelling and try again.</p>\n'
[10-May-2021 15:00] 127.0.0.1 POST http /insere/? 5xx INTERNAL SERVER ERROR
Traceback (most recent call last):
  File "/Users/rmj/webdev/BackEnd/flask_api_updown_auth/venv/lib/python3.7/site-packages/flask/app.py", line 1950, in full_dispatch_request
    rv = self.dispatch_request()
  File "/Users/rmj/webdev/BackEnd/flask_api_updown_auth/venv/lib/python3.7/site-packages/flask/app.py", line 1926, in dispatch_request
    self.raise_routing_exception(req)
  File "/Users/rmj/webdev/BackEnd/flask_api_updown_auth/venv/lib/python3.7/site-packages/flask/app.py", line 1908, in raise_routing_exception
    raise request.routing_exception
  File "/Users/rmj/webdev/BackEnd/flask_api_updown_auth/venv/lib/python3.7/site-packages/flask/ctx.py", line 350, in match_request
    result = self.url_adapter.match(return_rule=True)
  File "/Users/rmj/webdev/BackEnd/flask_api_updown_auth/venv/lib/python3.7/site-packages/werkzeug/routing.py", line 1945, in match
    raise NotFound()
werkzeug.exceptions.NotFound: 404 Not Found: The requested URL was not found on the server. If you entered the URL manually please check your spelling and try again.

[10-May-2021 15:00] 127.0.0.1 POST http /insere/? 404 NOT FOUND b'<!DOCTYPE HTML PUBLIC "-//W3C//DTD HTML 3.2 Final//EN">\n<title>404 Not Found</title>\n<h1>Not Found</h1>\n<p>The requested URL was not found on the server. If you entered the URL manually please check your spelling and try again.</p>\n'
[10-May-2021 15:02] 127.0.0.1 POST http /insere/coiso.txt? 5xx INTERNAL SERVER ERROR
Traceback (most recent call last):
  File "/Users/rmj/webdev/BackEnd/flask_api_updown_auth/venv/lib/python3.7/site-packages/flask/app.py", line 1950, in full_dispatch_request
    rv = self.dispatch_request()
  File "/Users/rmj/webdev/BackEnd/flask_api_updown_auth/venv/lib/python3.7/site-packages/flask/app.py", line 1926, in dispatch_request
    self.raise_routing_exception(req)
  File "/Users/rmj/webdev/BackEnd/flask_api_updown_auth/venv/lib/python3.7/site-packages/flask/app.py", line 1908, in raise_routing_exception
    raise request.routing_exception
  File "/Users/rmj/webdev/BackEnd/flask_api_updown_auth/venv/lib/python3.7/site-packages/flask/ctx.py", line 350, in match_request
    result = self.url_adapter.match(return_rule=True)
  File "/Users/rmj/webdev/BackEnd/flask_api_updown_auth/venv/lib/python3.7/site-packages/werkzeug/routing.py", line 1945, in match
    raise NotFound()
werkzeug.exceptions.NotFound: 404 Not Found: The requested URL was not found on the server. If you entered the URL manually please check your spelling and try again.

[10-May-2021 15:02] 127.0.0.1 POST http /insere/coiso.txt? 404 NOT FOUND b'<!DOCTYPE HTML PUBLIC "-//W3C//DTD HTML 3.2 Final//EN">\n<title>404 Not Found</title>\n<h1>Not Found</h1>\n<p>The requested URL was not found on the server. If you entered the URL manually please check your spelling and try again.</p>\n'
[10-May-2021 15:03] 127.0.0.1 POST http /insere_arquivo/? 5xx INTERNAL SERVER ERROR
Traceback (most recent call last):
  File "/Users/rmj/webdev/BackEnd/flask_api_updown_auth/venv/lib/python3.7/site-packages/flask/app.py", line 1950, in full_dispatch_request
    rv = self.dispatch_request()
  File "/Users/rmj/webdev/BackEnd/flask_api_updown_auth/venv/lib/python3.7/site-packages/flask/app.py", line 1926, in dispatch_request
    self.raise_routing_exception(req)
  File "/Users/rmj/webdev/BackEnd/flask_api_updown_auth/venv/lib/python3.7/site-packages/flask/app.py", line 1908, in raise_routing_exception
    raise request.routing_exception
  File "/Users/rmj/webdev/BackEnd/flask_api_updown_auth/venv/lib/python3.7/site-packages/flask/ctx.py", line 350, in match_request
    result = self.url_adapter.match(return_rule=True)
  File "/Users/rmj/webdev/BackEnd/flask_api_updown_auth/venv/lib/python3.7/site-packages/werkzeug/routing.py", line 1945, in match
    raise NotFound()
werkzeug.exceptions.NotFound: 404 Not Found: The requested URL was not found on the server. If you entered the URL manually please check your spelling and try again.

[10-May-2021 15:03] 127.0.0.1 POST http /insere_arquivo/? 404 NOT FOUND b'<!DOCTYPE HTML PUBLIC "-//W3C//DTD HTML 3.2 Final//EN">\n<title>404 Not Found</title>\n<h1>Not Found</h1>\n<p>The requested URL was not found on the server. If you entered the URL manually please check your spelling and try again.</p>\n'
[10-May-2021 15:03] 127.0.0.1 POST http /insere_arquivo/a? 201 CREATED b''
[10-May-2021 15:03] 127.0.0.1 POST http /insere_arquivo? 5xx INTERNAL SERVER ERROR
Traceback (most recent call last):
  File "/Users/rmj/webdev/BackEnd/flask_api_updown_auth/venv/lib/python3.7/site-packages/flask/app.py", line 1950, in full_dispatch_request
    rv = self.dispatch_request()
  File "/Users/rmj/webdev/BackEnd/flask_api_updown_auth/venv/lib/python3.7/site-packages/flask/app.py", line 1936, in dispatch_request
    return self.view_functions[rule.endpoint](**req.view_args)
TypeError: insere_arquivo() missing 1 required positional argument: 'arquivo'

[10-May-2021 15:06] 127.0.0.1 POST http /insere_arquivo? 5xx INTERNAL SERVER ERROR
Traceback (most recent call last):
  File "/Users/rmj/webdev/BackEnd/flask_api_updown_auth/venv/lib/python3.7/site-packages/flask/app.py", line 1950, in full_dispatch_request
    rv = self.dispatch_request()
  File "/Users/rmj/webdev/BackEnd/flask_api_updown_auth/venv/lib/python3.7/site-packages/flask/app.py", line 1926, in dispatch_request
    self.raise_routing_exception(req)
  File "/Users/rmj/webdev/BackEnd/flask_api_updown_auth/venv/lib/python3.7/site-packages/flask/app.py", line 1908, in raise_routing_exception
    raise request.routing_exception
  File "/Users/rmj/webdev/BackEnd/flask_api_updown_auth/venv/lib/python3.7/site-packages/flask/ctx.py", line 350, in match_request
    result = self.url_adapter.match(return_rule=True)
  File "/Users/rmj/webdev/BackEnd/flask_api_updown_auth/venv/lib/python3.7/site-packages/werkzeug/routing.py", line 1945, in match
    raise NotFound()
werkzeug.exceptions.NotFound: 404 Not Found: The requested URL was not found on the server. If you entered the URL manually please check your spelling and try again.

[10-May-2021 15:06] 127.0.0.1 POST http /insere_arquivo? 404 NOT FOUND b'<!DOCTYPE HTML PUBLIC "-//W3C//DTD HTML 3.2 Final//EN">\n<title>404 Not Found</title>\n<h1>Not Found</h1>\n<p>The requested URL was not found on the server. If you entered the URL manually please check your spelling and try again.</p>\n'
[10-May-2021 15:07] 127.0.0.1 POST http /insere_arquivo? 5xx INTERNAL SERVER ERROR
Traceback (most recent call last):
  File "/Users/rmj/webdev/BackEnd/flask_api_updown_auth/venv/lib/python3.7/site-packages/flask/app.py", line 1950, in full_dispatch_request
    rv = self.dispatch_request()
  File "/Users/rmj/webdev/BackEnd/flask_api_updown_auth/venv/lib/python3.7/site-packages/flask/app.py", line 1926, in dispatch_request
    self.raise_routing_exception(req)
  File "/Users/rmj/webdev/BackEnd/flask_api_updown_auth/venv/lib/python3.7/site-packages/flask/app.py", line 1908, in raise_routing_exception
    raise request.routing_exception
  File "/Users/rmj/webdev/BackEnd/flask_api_updown_auth/venv/lib/python3.7/site-packages/flask/ctx.py", line 350, in match_request
    result = self.url_adapter.match(return_rule=True)
  File "/Users/rmj/webdev/BackEnd/flask_api_updown_auth/venv/lib/python3.7/site-packages/werkzeug/routing.py", line 1945, in match
    raise NotFound()
werkzeug.exceptions.NotFound: 404 Not Found: The requested URL was not found on the server. If you entered the URL manually please check your spelling and try again.

[10-May-2021 15:07] 127.0.0.1 POST http /insere_arquivo? 404 NOT FOUND b'<!DOCTYPE HTML PUBLIC "-//W3C//DTD HTML 3.2 Final//EN">\n<title>404 Not Found</title>\n<h1>Not Found</h1>\n<p>The requested URL was not found on the server. If you entered the URL manually please check your spelling and try again.</p>\n'
[10-May-2021 15:07] 127.0.0.1 POST http /insere_arquivo/coiso.png? 201 CREATED b''
[10-May-2021 15:07] 127.0.0.1 POST http /insere_arquivo/coiso.png? 201 CREATED b''
[10-May-2021 15:48] 127.0.0.1 POST http /insere_arquivo/arquivo.txt? 201 CREATED b''
[10-May-2021 15:49] 127.0.0.1 POST http /insere_arquivo/arquivo.txt? 5xx INTERNAL SERVER ERROR
Traceback (most recent call last):
  File "/Users/rmj/webdev/BackEnd/flask_api_updown_auth/venv/lib/python3.7/site-packages/flask/app.py", line 1950, in full_dispatch_request
    rv = self.dispatch_request()
  File "/Users/rmj/webdev/BackEnd/flask_api_updown_auth/venv/lib/python3.7/site-packages/flask/app.py", line 1936, in dispatch_request
    return self.view_functions[rule.endpoint](**req.view_args)
  File "/Users/rmj/webdev/BackEnd/flask_api_updown_auth/apiupdown/__init__.py", line 116, in insere_arquivo
    recebido = request.data()
TypeError: 'bytes' object is not callable

[10-May-2021 15:49] 127.0.0.1 POST http /insere_arquivo/arquivo.txt? 201 CREATED b''
[10-May-2021 15:50] 127.0.0.1 POST http /insere_arquivo/arquivo.txt? 201 CREATED b''
[10-May-2021 15:52] 127.0.0.1 POST http /insere_arquivo/arquivo.txt? 5xx INTERNAL SERVER ERROR
Traceback (most recent call last):
  File "/Users/rmj/webdev/BackEnd/flask_api_updown_auth/venv/lib/python3.7/site-packages/flask/app.py", line 1950, in full_dispatch_request
    rv = self.dispatch_request()
  File "/Users/rmj/webdev/BackEnd/flask_api_updown_auth/venv/lib/python3.7/site-packages/flask/app.py", line 1936, in dispatch_request
    return self.view_functions[rule.endpoint](**req.view_args)
  File "/Users/rmj/webdev/BackEnd/flask_api_updown_auth/apiupdown/__init__.py", line 118, in insere_arquivo
    with open(recebido, "rb") as f:
FileNotFoundError: [Errno 2] No such file or directory: b'coiso\ncoisa\ncoisada\n'

[10-May-2021 15:52] 127.0.0.1 POST http /insere_arquivo/arquivo.txt? 5xx INTERNAL SERVER ERROR
Traceback (most recent call last):
  File "/Users/rmj/webdev/BackEnd/flask_api_updown_auth/venv/lib/python3.7/site-packages/flask/app.py", line 1950, in full_dispatch_request
    rv = self.dispatch_request()
  File "/Users/rmj/webdev/BackEnd/flask_api_updown_auth/venv/lib/python3.7/site-packages/flask/app.py", line 1936, in dispatch_request
    return self.view_functions[rule.endpoint](**req.view_args)
  File "/Users/rmj/webdev/BackEnd/flask_api_updown_auth/apiupdown/__init__.py", line 118, in insere_arquivo
    with open(recebido, "rb") as f:
FileNotFoundError: [Errno 2] No such file or directory: b'coiso\ncoisa\ncoisada\n'

[10-May-2021 15:52] 127.0.0.1 POST http /insere_arquivo/arquivo.txt? 5xx INTERNAL SERVER ERROR
Traceback (most recent call last):
  File "/Users/rmj/webdev/BackEnd/flask_api_updown_auth/venv/lib/python3.7/site-packages/flask/app.py", line 1950, in full_dispatch_request
    rv = self.dispatch_request()
  File "/Users/rmj/webdev/BackEnd/flask_api_updown_auth/venv/lib/python3.7/site-packages/flask/app.py", line 1936, in dispatch_request
    return self.view_functions[rule.endpoint](**req.view_args)
  File "/Users/rmj/webdev/BackEnd/flask_api_updown_auth/apiupdown/__init__.py", line 118, in insere_arquivo
    while byte != b"":
UnboundLocalError: local variable 'byte' referenced before assignment

[10-May-2021 15:52] 127.0.0.1 POST http /insere_arquivo/arquivo.txt? 5xx INTERNAL SERVER ERROR
Traceback (most recent call last):
  File "/Users/rmj/webdev/BackEnd/flask_api_updown_auth/venv/lib/python3.7/site-packages/flask/app.py", line 1950, in full_dispatch_request
    rv = self.dispatch_request()
  File "/Users/rmj/webdev/BackEnd/flask_api_updown_auth/venv/lib/python3.7/site-packages/flask/app.py", line 1936, in dispatch_request
    return self.view_functions[rule.endpoint](**req.view_args)
  File "/Users/rmj/webdev/BackEnd/flask_api_updown_auth/apiupdown/__init__.py", line 120, in insere_arquivo
    recebido = f.read(1)
NameError: name 'f' is not defined

[10-May-2021 15:52] 127.0.0.1 POST http /insere_arquivo/arquivo.txt? 5xx INTERNAL SERVER ERROR
Traceback (most recent call last):
  File "/Users/rmj/webdev/BackEnd/flask_api_updown_auth/venv/lib/python3.7/site-packages/flask/app.py", line 1950, in full_dispatch_request
    rv = self.dispatch_request()
  File "/Users/rmj/webdev/BackEnd/flask_api_updown_auth/venv/lib/python3.7/site-packages/flask/app.py", line 1936, in dispatch_request
    return self.view_functions[rule.endpoint](**req.view_args)
  File "/Users/rmj/webdev/BackEnd/flask_api_updown_auth/apiupdown/__init__.py", line 120, in insere_arquivo
    recebido = f.read(1)
NameError: name 'f' is not defined

[10-May-2021 15:55] 127.0.0.1 POST http /insere_arquivo/arquivo.txt? 201 CREATED b''
[10-May-2021 15:56] 127.0.0.1 POST http /insere_arquivo/arquivo.txt? 201 CREATED b''
[10-May-2021 15:57] 127.0.0.1 POST http /insere_arquivo/arquivo.txt? 201 CREATED b''
[10-May-2021 15:58] 127.0.0.1 POST http /insere_arquivo/arquivo.txt? 201 CREATED b''
[10-May-2021 15:58] 127.0.0.1 POST http /insere_arquivo/arquivo.txt? 201 CREATED b''
[10-May-2021 15:59] 127.0.0.1 POST http /insere_arquivo/arquivo.txt? 201 CREATED b''
[10-May-2021 15:59] 127.0.0.1 POST http /insere_arquivo/arquivo.txt? 201 CREATED b''
[10-May-2021 16:01] 127.0.0.1 POST http /insere_arquivo/arquivo.txt? 5xx INTERNAL SERVER ERROR
Traceback (most recent call last):
  File "/Users/rmj/webdev/BackEnd/flask_api_updown_auth/venv/lib/python3.7/site-packages/flask/app.py", line 1950, in full_dispatch_request
    rv = self.dispatch_request()
  File "/Users/rmj/webdev/BackEnd/flask_api_updown_auth/venv/lib/python3.7/site-packages/flask/app.py", line 1936, in dispatch_request
    return self.view_functions[rule.endpoint](**req.view_args)
  File "/Users/rmj/webdev/BackEnd/flask_api_updown_auth/apiupdown/__init__.py", line 118, in insere_arquivo
    formatado = recebido.decode("utf-8")
AttributeError: 'str' object has no attribute 'decode'

[10-May-2021 16:02] 127.0.0.1 POST http /insere_arquivo/arquivo.txt? 5xx INTERNAL SERVER ERROR
Traceback (most recent call last):
  File "/Users/rmj/webdev/BackEnd/flask_api_updown_auth/venv/lib/python3.7/site-packages/flask/app.py", line 1950, in full_dispatch_request
    rv = self.dispatch_request()
  File "/Users/rmj/webdev/BackEnd/flask_api_updown_auth/venv/lib/python3.7/site-packages/flask/app.py", line 1936, in dispatch_request
    return self.view_functions[rule.endpoint](**req.view_args)
  File "/Users/rmj/webdev/BackEnd/flask_api_updown_auth/apiupdown/__init__.py", line 118, in insere_arquivo
    formatado = recebido.decode("utf-8")
AttributeError: 'str' object has no attribute 'decode'

[10-May-2021 16:03] 127.0.0.1 POST http /insere_arquivo/arquivo.txt? 5xx INTERNAL SERVER ERROR
Traceback (most recent call last):
  File "/Users/rmj/webdev/BackEnd/flask_api_updown_auth/venv/lib/python3.7/site-packages/flask/app.py", line 1950, in full_dispatch_request
    rv = self.dispatch_request()
  File "/Users/rmj/webdev/BackEnd/flask_api_updown_auth/venv/lib/python3.7/site-packages/flask/app.py", line 1936, in dispatch_request
    return self.view_functions[rule.endpoint](**req.view_args)
  File "/Users/rmj/webdev/BackEnd/flask_api_updown_auth/apiupdown/__init__.py", line 121, in insere_arquivo
    print(formatado)
NameError: name 'formatado' is not defined

[10-May-2021 16:03] 127.0.0.1 POST http /insere_arquivo/arquivo.txt? 201 CREATED b''
[10-May-2021 16:04] 127.0.0.1 POST http /insere_arquivo/arquivo.txt? 201 CREATED b''
[10-May-2021 16:04] 127.0.0.1 POST http /insere_arquivo/arquivo.txt? 201 CREATED b''
[10-May-2021 16:05] 127.0.0.1 POST http /insere_arquivo/arquivo.txt? 201 CREATED b''
[10-May-2021 16:05] 127.0.0.1 POST http /insere_arquivo/arquivo.txt? 201 CREATED b''
[10-May-2021 16:05] 127.0.0.1 POST http /insere_arquivo/arquivo.txt? 201 CREATED b''
[10-May-2021 16:06] 127.0.0.1 POST http /insere_arquivo/arquivo.txt? 201 CREATED b''
[10-May-2021 16:13] 127.0.0.1 POST http /insere_arquivo/arquivo.txt? 5xx INTERNAL SERVER ERROR
Traceback (most recent call last):
  File "/Users/rmj/webdev/BackEnd/flask_api_updown_auth/venv/lib/python3.7/site-packages/flask/app.py", line 1950, in full_dispatch_request
    rv = self.dispatch_request()
  File "/Users/rmj/webdev/BackEnd/flask_api_updown_auth/venv/lib/python3.7/site-packages/flask/app.py", line 1936, in dispatch_request
    return self.view_functions[rule.endpoint](**req.view_args)
  File "/Users/rmj/webdev/BackEnd/flask_api_updown_auth/apiupdown/__init__.py", line 119, in insere_arquivo
    s = StringIO.StringIO(formatado)
AttributeError: type object '_io.StringIO' has no attribute 'StringIO'

[10-May-2021 16:13] 127.0.0.1 POST http /insere_arquivo/arquivo.txt? 201 CREATED b''
[10-May-2021 16:13] 127.0.0.1 POST http /insere_arquivo/arquivo.txt? 201 CREATED b''
[10-May-2021 16:14] 127.0.0.1 POST http /insere_arquivo/arquivo.txt? 201 CREATED b''
[10-May-2021 16:15] 127.0.0.1 POST http /insere_arquivo/arquivo.txt? 201 CREATED b''
[10-May-2021 16:15] 127.0.0.1 POST http /insere_arquivo/arquivo.txt? 201 CREATED b''
[10-May-2021 16:17] 127.0.0.1 POST http /insere_arquivo/arquivo.txt? 201 CREATED b''
[10-May-2021 16:17] 127.0.0.1 POST http /insere_arquivo/arquivo.txt? 5xx INTERNAL SERVER ERROR
Traceback (most recent call last):
  File "/Users/rmj/webdev/BackEnd/flask_api_updown_auth/venv/lib/python3.7/site-packages/flask/app.py", line 1950, in full_dispatch_request
    rv = self.dispatch_request()
  File "/Users/rmj/webdev/BackEnd/flask_api_updown_auth/venv/lib/python3.7/site-packages/flask/app.py", line 1936, in dispatch_request
    return self.view_functions[rule.endpoint](**req.view_args)
  File "/Users/rmj/webdev/BackEnd/flask_api_updown_auth/apiupdown/__init__.py", line 120, in insere_arquivo
    formatado.pop(0)
AttributeError: '_io.StringIO' object has no attribute 'pop'

[10-May-2021 16:17] 127.0.0.1 POST http /insere_arquivo/arquivo.txt? 201 CREATED b''
[10-May-2021 16:18] 127.0.0.1 POST http /insere_arquivo/arquivo.txt? 5xx INTERNAL SERVER ERROR
Traceback (most recent call last):
  File "/Users/rmj/webdev/BackEnd/flask_api_updown_auth/venv/lib/python3.7/site-packages/flask/app.py", line 1950, in full_dispatch_request
    rv = self.dispatch_request()
  File "/Users/rmj/webdev/BackEnd/flask_api_updown_auth/venv/lib/python3.7/site-packages/flask/app.py", line 1936, in dispatch_request
    return self.view_functions[rule.endpoint](**req.view_args)
  File "/Users/rmj/webdev/BackEnd/flask_api_updown_auth/apiupdown/__init__.py", line 120, in insere_arquivo
    formatado.pop()
AttributeError: '_io.StringIO' object has no attribute 'pop'

[10-May-2021 16:19] 127.0.0.1 POST http /insere_arquivo/arquivo.txt? 5xx INTERNAL SERVER ERROR
Traceback (most recent call last):
  File "/Users/rmj/webdev/BackEnd/flask_api_updown_auth/venv/lib/python3.7/site-packages/flask/app.py", line 1950, in full_dispatch_request
    rv = self.dispatch_request()
  File "/Users/rmj/webdev/BackEnd/flask_api_updown_auth/venv/lib/python3.7/site-packages/flask/app.py", line 1936, in dispatch_request
    return self.view_functions[rule.endpoint](**req.view_args)
  File "/Users/rmj/webdev/BackEnd/flask_api_updown_auth/apiupdown/__init__.py", line 120, in insere_arquivo
    formatado[0]
TypeError: '_io.StringIO' object is not subscriptable

[10-May-2021 16:19] 127.0.0.1 POST http /insere_arquivo/arquivo.txt? 5xx INTERNAL SERVER ERROR
Traceback (most recent call last):
  File "/Users/rmj/webdev/BackEnd/flask_api_updown_auth/venv/lib/python3.7/site-packages/flask/app.py", line 1950, in full_dispatch_request
    rv = self.dispatch_request()
  File "/Users/rmj/webdev/BackEnd/flask_api_updown_auth/venv/lib/python3.7/site-packages/flask/app.py", line 1936, in dispatch_request
    return self.view_functions[rule.endpoint](**req.view_args)
  File "/Users/rmj/webdev/BackEnd/flask_api_updown_auth/apiupdown/__init__.py", line 121, in insere_arquivo
    linhas.append(linha)
NameError: name 'linhas' is not defined

[10-May-2021 16:20] 127.0.0.1 POST http /insere_arquivo/arquivo.txt? 201 CREATED b''
[10-May-2021 16:20] 127.0.0.1 POST http /insere_arquivo/arquivo.txt? 201 CREATED b''
[10-May-2021 16:20] 127.0.0.1 POST http /insere_arquivo/arquivo.txt? 5xx INTERNAL SERVER ERROR
Traceback (most recent call last):
  File "/Users/rmj/webdev/BackEnd/flask_api_updown_auth/venv/lib/python3.7/site-packages/flask/app.py", line 1950, in full_dispatch_request
    rv = self.dispatch_request()
  File "/Users/rmj/webdev/BackEnd/flask_api_updown_auth/venv/lib/python3.7/site-packages/flask/app.py", line 1936, in dispatch_request
    return self.view_functions[rule.endpoint](**req.view_args)
  File "/Users/rmj/webdev/BackEnd/flask_api_updown_auth/apiupdown/__init__.py", line 123, in insere_arquivo
    print(formatado[0])
TypeError: '_io.StringIO' object is not subscriptable

[10-May-2021 16:21] 127.0.0.1 POST http /insere_arquivo/arquivo.txt? 201 CREATED b''
[10-May-2021 16:21] 127.0.0.1 POST http /insere_arquivo/arquivo.txt? 201 CREATED b''
[10-May-2021 16:21] 127.0.0.1 POST http /insere_arquivo/arquivo.txt? 201 CREATED b''
[10-May-2021 16:22] 127.0.0.1 POST http /insere_arquivo/arquivo.txt? 5xx INTERNAL SERVER ERROR
Traceback (most recent call last):
  File "/Users/rmj/webdev/BackEnd/flask_api_updown_auth/venv/lib/python3.7/site-packages/flask/app.py", line 1950, in full_dispatch_request
    rv = self.dispatch_request()
  File "/Users/rmj/webdev/BackEnd/flask_api_updown_auth/venv/lib/python3.7/site-packages/flask/app.py", line 1936, in dispatch_request
    return self.view_functions[rule.endpoint](**req.view_args)
  File "/Users/rmj/webdev/BackEnd/flask_api_updown_auth/apiupdown/__init__.py", line 122, in insere_arquivo
    linha = linha.remove('\\n')
AttributeError: 'str' object has no attribute 'remove'

[10-May-2021 16:22] 127.0.0.1 POST http /insere_arquivo/arquivo.txt? 5xx INTERNAL SERVER ERROR
Traceback (most recent call last):
  File "/Users/rmj/webdev/BackEnd/flask_api_updown_auth/venv/lib/python3.7/site-packages/flask/app.py", line 1950, in full_dispatch_request
    rv = self.dispatch_request()
  File "/Users/rmj/webdev/BackEnd/flask_api_updown_auth/venv/lib/python3.7/site-packages/flask/app.py", line 1936, in dispatch_request
    return self.view_functions[rule.endpoint](**req.view_args)
  File "/Users/rmj/webdev/BackEnd/flask_api_updown_auth/apiupdown/__init__.py", line 122, in insere_arquivo
    linha = linha.replace('\\n')
TypeError: replace() takes at least 2 arguments (1 given)

[10-May-2021 16:22] 127.0.0.1 POST http /insere_arquivo/arquivo.txt? 201 CREATED b''
[10-May-2021 16:23] 127.0.0.1 POST http /insere_arquivo/arquivo.txt? 201 CREATED b''
[10-May-2021 16:25] 127.0.0.1 POST http /insere_arquivo/arquivo.txt? 201 CREATED b''
[10-May-2021 16:28] 127.0.0.1 POST http /insere_arquivo/arquivo.txt? 5xx INTERNAL SERVER ERROR
Traceback (most recent call last):
  File "/Users/rmj/webdev/BackEnd/flask_api_updown_auth/venv/lib/python3.7/site-packages/flask/app.py", line 1950, in full_dispatch_request
    rv = self.dispatch_request()
  File "/Users/rmj/webdev/BackEnd/flask_api_updown_auth/venv/lib/python3.7/site-packages/flask/app.py", line 1936, in dispatch_request
    return self.view_functions[rule.endpoint](**req.view_args)
  File "/Users/rmj/webdev/BackEnd/flask_api_updown_auth/apiupdown/__init__.py", line 125, in insere_arquivo
    qtd_registros = int(linha[0][46:51])
ValueError: invalid literal for int() with base 10: ''

[10-May-2021 16:29] 127.0.0.1 POST http /insere_arquivo/arquivo.txt? 201 CREATED b''
[10-May-2021 16:29] 127.0.0.1 POST http /insere_arquivo/arquivo.txt? 201 CREATED b''
[10-May-2021 16:29] 127.0.0.1 POST http /insere_arquivo/arquivo.txt? 201 CREATED b''
[10-May-2021 16:29] 127.0.0.1 POST http /insere_arquivo/arquivo.txt? 201 CREATED b''
[10-May-2021 16:30] 127.0.0.1 POST http /insere_arquivo/arquivo.txt? 201 CREATED b''
[10-May-2021 16:30] 127.0.0.1 POST http /insere_arquivo/arquivo.txt? 201 CREATED b''
[10-May-2021 16:30] 127.0.0.1 POST http /insere_arquivo/arquivo.txt? 5xx INTERNAL SERVER ERROR
Traceback (most recent call last):
  File "/Users/rmj/webdev/BackEnd/flask_api_updown_auth/venv/lib/python3.7/site-packages/flask/app.py", line 1950, in full_dispatch_request
    rv = self.dispatch_request()
  File "/Users/rmj/webdev/BackEnd/flask_api_updown_auth/venv/lib/python3.7/site-packages/flask/app.py", line 1936, in dispatch_request
    return self.view_functions[rule.endpoint](**req.view_args)
  File "/Users/rmj/webdev/BackEnd/flask_api_updown_auth/apiupdown/__init__.py", line 127, in insere_arquivo
    for i in range(1..qtd_registros):
AttributeError: 'float' object has no attribute 'qtd_registros'

[10-May-2021 16:31] 127.0.0.1 POST http /insere_arquivo/arquivo.txt? 201 CREATED b''
[10-May-2021 16:32] 127.0.0.1 POST http /insere_arquivo/arquivo.txt? 5xx INTERNAL SERVER ERROR
Traceback (most recent call last):
  File "/Users/rmj/webdev/BackEnd/flask_api_updown_auth/venv/lib/python3.7/site-packages/flask/app.py", line 1950, in full_dispatch_request
    rv = self.dispatch_request()
  File "/Users/rmj/webdev/BackEnd/flask_api_updown_auth/venv/lib/python3.7/site-packages/flask/app.py", line 1936, in dispatch_request
    return self.view_functions[rule.endpoint](**req.view_args)
  File "/Users/rmj/webdev/BackEnd/flask_api_updown_auth/apiupdown/__init__.py", line 128, in insere_arquivo
    adiciona_no_banco(linha)
  File "/Users/rmj/webdev/BackEnd/flask_api_updown_auth/apiupdown/__init__.py", line 84, in adiciona_no_banco
    lin = " ".join(linha[0].split())
TypeError: 'int' object is not subscriptable

[10-May-2021 16:32] 127.0.0.1 POST http /insere_arquivo/arquivo.txt? 5xx INTERNAL SERVER ERROR
Traceback (most recent call last):
  File "/Users/rmj/webdev/BackEnd/flask_api_updown_auth/venv/lib/python3.7/site-packages/flask/app.py", line 1950, in full_dispatch_request
    rv = self.dispatch_request()
  File "/Users/rmj/webdev/BackEnd/flask_api_updown_auth/venv/lib/python3.7/site-packages/flask/app.py", line 1936, in dispatch_request
    return self.view_functions[rule.endpoint](**req.view_args)
  File "/Users/rmj/webdev/BackEnd/flask_api_updown_auth/apiupdown/__init__.py", line 128, in insere_arquivo
    adiciona_no_banco(l)
  File "/Users/rmj/webdev/BackEnd/flask_api_updown_auth/apiupdown/__init__.py", line 84, in adiciona_no_banco
    lin = " ".join(linha[0].split())
TypeError: 'int' object is not subscriptable

[10-May-2021 16:32] 127.0.0.1 POST http /insere_arquivo/arquivo.txt? 5xx INTERNAL SERVER ERROR
Traceback (most recent call last):
  File "/Users/rmj/webdev/BackEnd/flask_api_updown_auth/venv/lib/python3.7/site-packages/flask/app.py", line 1950, in full_dispatch_request
    rv = self.dispatch_request()
  File "/Users/rmj/webdev/BackEnd/flask_api_updown_auth/venv/lib/python3.7/site-packages/flask/app.py", line 1936, in dispatch_request
    return self.view_functions[rule.endpoint](**req.view_args)
  File "/Users/rmj/webdev/BackEnd/flask_api_updown_auth/apiupdown/__init__.py", line 128, in insere_arquivo
    adiciona_no_banco(l)
  File "/Users/rmj/webdev/BackEnd/flask_api_updown_auth/apiupdown/__init__.py", line 84, in adiciona_no_banco
    lin = " ".join(linha[0].split())
TypeError: 'int' object is not subscriptable

[10-May-2021 16:33] 127.0.0.1 POST http /insere_arquivo/arquivo.txt? 201 CREATED b''
[10-May-2021 16:36] 127.0.0.1 POST http /insere_arquivo/arquivo.txt? 5xx INTERNAL SERVER ERROR
Traceback (most recent call last):
  File "/Users/rmj/webdev/BackEnd/flask_api_updown_auth/venv/lib/python3.7/site-packages/flask/app.py", line 1950, in full_dispatch_request
    rv = self.dispatch_request()
  File "/Users/rmj/webdev/BackEnd/flask_api_updown_auth/venv/lib/python3.7/site-packages/flask/app.py", line 1936, in dispatch_request
    return self.view_functions[rule.endpoint](**req.view_args)
  File "/Users/rmj/webdev/BackEnd/flask_api_updown_auth/apiupdown/__init__.py", line 132, in insere_arquivo
    'msg'     : "Adicionados " + qtd_registros + " do lote " + lote + ".",
TypeError: can only concatenate str (not "int") to str

[10-May-2021 16:37] 127.0.0.1 POST http /insere_arquivo/arquivo.txt? 5xx INTERNAL SERVER ERROR
Traceback (most recent call last):
  File "/Users/rmj/webdev/BackEnd/flask_api_updown_auth/venv/lib/python3.7/site-packages/flask/app.py", line 1950, in full_dispatch_request
    rv = self.dispatch_request()
  File "/Users/rmj/webdev/BackEnd/flask_api_updown_auth/venv/lib/python3.7/site-packages/flask/app.py", line 1936, in dispatch_request
    return self.view_functions[rule.endpoint](**req.view_args)
  File "/Users/rmj/webdev/BackEnd/flask_api_updown_auth/apiupdown/__init__.py", line 132, in insere_arquivo
    'msg'     : "Adicionados " + qtd_registros + " do lote " + lote + ".",
TypeError: can only concatenate str (not "int") to str

[10-May-2021 16:37] 127.0.0.1 POST http /insere_arquivo/arquivo.txt? 5xx INTERNAL SERVER ERROR
Traceback (most recent call last):
  File "/Users/rmj/webdev/BackEnd/flask_api_updown_auth/venv/lib/python3.7/site-packages/flask/app.py", line 1950, in full_dispatch_request
    rv = self.dispatch_request()
  File "/Users/rmj/webdev/BackEnd/flask_api_updown_auth/venv/lib/python3.7/site-packages/flask/app.py", line 1936, in dispatch_request
    return self.view_functions[rule.endpoint](**req.view_args)
  File "/Users/rmj/webdev/BackEnd/flask_api_updown_auth/apiupdown/__init__.py", line 132, in insere_arquivo
    'msg'     : "Adicionados " + qtd_registros + " do lote " + lote + ".",
TypeError: can only concatenate str (not "int") to str

[10-May-2021 16:37] 127.0.0.1 POST http /insere_arquivo/arquivo.txt? 5xx INTERNAL SERVER ERROR
Traceback (most recent call last):
  File "/Users/rmj/webdev/BackEnd/flask_api_updown_auth/venv/lib/python3.7/site-packages/flask/app.py", line 1950, in full_dispatch_request
    rv = self.dispatch_request()
  File "/Users/rmj/webdev/BackEnd/flask_api_updown_auth/venv/lib/python3.7/site-packages/flask/app.py", line 1936, in dispatch_request
    return self.view_functions[rule.endpoint](**req.view_args)
  File "/Users/rmj/webdev/BackEnd/flask_api_updown_auth/apiupdown/__init__.py", line 133, in insere_arquivo
    return jsonify(msg), 201
NameError: name 'msg' is not defined

[10-May-2021 16:37] 127.0.0.1 POST http /insere_arquivo/arquivo.txt? 201 CREATED b'{}\n'
[10-May-2021 16:38] 127.0.0.1 POST http /insere_arquivo/arquivo.txt? 201 CREATED b'{\n  "msg": "Adicionados 10 do lote 0.", \n  "success": true\n}\n'
[10-May-2021 16:38] 127.0.0.1 POST http /insere_arquivo/arquivo.txt? 201 CREATED b'{\n  "msg": "Adicionados 1 do lote 0.", \n  "success": true\n}\n'
[10-May-2021 16:40] 127.0.0.1 POST http /insere_arquivo/arquivo.txt? 201 CREATED b'{\n  "msg": "Adicionados 1 do lote 0.", \n  "success": true\n}\n'
[10-May-2021 16:40] 127.0.0.1 POST http /insere_arquivo/arquivo.txt? 5xx INTERNAL SERVER ERROR
Traceback (most recent call last):
  File "/Users/rmj/webdev/BackEnd/flask_api_updown_auth/venv/lib/python3.7/site-packages/flask/app.py", line 1950, in full_dispatch_request
    rv = self.dispatch_request()
  File "/Users/rmj/webdev/BackEnd/flask_api_updown_auth/venv/lib/python3.7/site-packages/flask/app.py", line 1936, in dispatch_request
    return self.view_functions[rule.endpoint](**req.view_args)
  File "/Users/rmj/webdev/BackEnd/flask_api_updown_auth/apiupdown/__init__.py", line 129, in insere_arquivo
    lote = int(linhas[0][37:44])
ValueError: invalid literal for int() with base 10: 'LOTE000'

[10-May-2021 16:41] 127.0.0.1 POST http /insere_arquivo/arquivo.txt? 5xx INTERNAL SERVER ERROR
Traceback (most recent call last):
  File "/Users/rmj/webdev/BackEnd/flask_api_updown_auth/venv/lib/python3.7/site-packages/flask/app.py", line 1950, in full_dispatch_request
    rv = self.dispatch_request()
  File "/Users/rmj/webdev/BackEnd/flask_api_updown_auth/venv/lib/python3.7/site-packages/flask/app.py", line 1936, in dispatch_request
    return self.view_functions[rule.endpoint](**req.view_args)
  File "/Users/rmj/webdev/BackEnd/flask_api_updown_auth/apiupdown/__init__.py", line 129, in insere_arquivo
    lote = int(linhas[0][37:44])
ValueError: invalid literal for int() with base 10: 'LOTE000'

[10-May-2021 16:41] 127.0.0.1 POST http /insere_arquivo/arquivo.txt? 5xx INTERNAL SERVER ERROR
Traceback (most recent call last):
  File "/Users/rmj/webdev/BackEnd/flask_api_updown_auth/venv/lib/python3.7/site-packages/flask/app.py", line 1950, in full_dispatch_request
    rv = self.dispatch_request()
  File "/Users/rmj/webdev/BackEnd/flask_api_updown_auth/venv/lib/python3.7/site-packages/flask/app.py", line 1936, in dispatch_request
    return self.view_functions[rule.endpoint](**req.view_args)
  File "/Users/rmj/webdev/BackEnd/flask_api_updown_auth/apiupdown/__init__.py", line 129, in insere_arquivo
    lote = int(linhas[0][37:44])
ValueError: invalid literal for int() with base 10: 'LOTE000'

[10-May-2021 16:42] 127.0.0.1 POST http /insere_arquivo/arquivo.txt? 5xx INTERNAL SERVER ERROR
Traceback (most recent call last):
  File "/Users/rmj/webdev/BackEnd/flask_api_updown_auth/venv/lib/python3.7/site-packages/flask/app.py", line 1950, in full_dispatch_request
    rv = self.dispatch_request()
  File "/Users/rmj/webdev/BackEnd/flask_api_updown_auth/venv/lib/python3.7/site-packages/flask/app.py", line 1936, in dispatch_request
    return self.view_functions[rule.endpoint](**req.view_args)
  File "/Users/rmj/webdev/BackEnd/flask_api_updown_auth/apiupdown/__init__.py", line 129, in insere_arquivo
    lote = int(linhas[0][37:44])
ValueError: invalid literal for int() with base 10: 'LOTE000'

[10-May-2021 16:42] 127.0.0.1 POST http /insere_arquivo/arquivo.txt? 5xx INTERNAL SERVER ERROR
Traceback (most recent call last):
  File "/Users/rmj/webdev/BackEnd/flask_api_updown_auth/venv/lib/python3.7/site-packages/flask/app.py", line 1950, in full_dispatch_request
    rv = self.dispatch_request()
  File "/Users/rmj/webdev/BackEnd/flask_api_updown_auth/venv/lib/python3.7/site-packages/flask/app.py", line 1936, in dispatch_request
    return self.view_functions[rule.endpoint](**req.view_args)
  File "/Users/rmj/webdev/BackEnd/flask_api_updown_auth/apiupdown/__init__.py", line 129, in insere_arquivo
    lote = int(linhas[0][37:44])
ValueError: invalid literal for int() with base 10: 'LOTE000'

[10-May-2021 16:43] 127.0.0.1 POST http /insere_arquivo/arquivo.txt? 5xx INTERNAL SERVER ERROR
Traceback (most recent call last):
  File "/Users/rmj/webdev/BackEnd/flask_api_updown_auth/venv/lib/python3.7/site-packages/flask/app.py", line 1950, in full_dispatch_request
    rv = self.dispatch_request()
  File "/Users/rmj/webdev/BackEnd/flask_api_updown_auth/venv/lib/python3.7/site-packages/flask/app.py", line 1936, in dispatch_request
    return self.view_functions[rule.endpoint](**req.view_args)
  File "/Users/rmj/webdev/BackEnd/flask_api_updown_auth/apiupdown/__init__.py", line 129, in insere_arquivo
    lote = int(linhas[0][37:44])
ValueError: invalid literal for int() with base 10: 'LOTE000'

[10-May-2021 16:44] 127.0.0.1 POST http /insere_arquivo/arquivo.txt? 5xx INTERNAL SERVER ERROR
Traceback (most recent call last):
  File "/Users/rmj/webdev/BackEnd/flask_api_updown_auth/venv/lib/python3.7/site-packages/flask/app.py", line 1950, in full_dispatch_request
    rv = self.dispatch_request()
  File "/Users/rmj/webdev/BackEnd/flask_api_updown_auth/venv/lib/python3.7/site-packages/flask/app.py", line 1936, in dispatch_request
    return self.view_functions[rule.endpoint](**req.view_args)
  File "/Users/rmj/webdev/BackEnd/flask_api_updown_auth/apiupdown/__init__.py", line 126, in insere_arquivo
    lote = int(linhas[0][37:45])
ValueError: invalid literal for int() with base 10: 'LOTE0001'

[10-May-2021 16:44] 127.0.0.1 POST http /insere_arquivo/arquivo.txt? 5xx INTERNAL SERVER ERROR
Traceback (most recent call last):
  File "/Users/rmj/webdev/BackEnd/flask_api_updown_auth/venv/lib/python3.7/site-packages/flask/app.py", line 1950, in full_dispatch_request
    rv = self.dispatch_request()
  File "/Users/rmj/webdev/BackEnd/flask_api_updown_auth/venv/lib/python3.7/site-packages/flask/app.py", line 1936, in dispatch_request
    return self.view_functions[rule.endpoint](**req.view_args)
  File "/Users/rmj/webdev/BackEnd/flask_api_updown_auth/apiupdown/__init__.py", line 126, in insere_arquivo
    lote = int(linhas[0][37:45])
ValueError: invalid literal for int() with base 10: 'LOTE0001'

[10-May-2021 16:45] 127.0.0.1 POST http /insere_arquivo/arquivo.txt? 5xx INTERNAL SERVER ERROR
Traceback (most recent call last):
  File "/Users/rmj/webdev/BackEnd/flask_api_updown_auth/venv/lib/python3.7/site-packages/flask/app.py", line 1950, in full_dispatch_request
    rv = self.dispatch_request()
  File "/Users/rmj/webdev/BackEnd/flask_api_updown_auth/venv/lib/python3.7/site-packages/flask/app.py", line 1936, in dispatch_request
    return self.view_functions[rule.endpoint](**req.view_args)
  File "/Users/rmj/webdev/BackEnd/flask_api_updown_auth/apiupdown/__init__.py", line 126, in insere_arquivo
    lote = int(linhas[0][37:45])
ValueError: invalid literal for int() with base 10: 'LOTE0001'

[10-May-2021 16:45] 127.0.0.1 POST http /insere_arquivo/arquivo.txt? 5xx INTERNAL SERVER ERROR
Traceback (most recent call last):
  File "/Users/rmj/webdev/BackEnd/flask_api_updown_auth/venv/lib/python3.7/site-packages/flask/app.py", line 1950, in full_dispatch_request
    rv = self.dispatch_request()
  File "/Users/rmj/webdev/BackEnd/flask_api_updown_auth/venv/lib/python3.7/site-packages/flask/app.py", line 1936, in dispatch_request
    return self.view_functions[rule.endpoint](**req.view_args)
  File "/Users/rmj/webdev/BackEnd/flask_api_updown_auth/apiupdown/__init__.py", line 126, in insere_arquivo
    lote = int(linhas[0][37:45])
ValueError: invalid literal for int() with base 10: 'LOTE0001'

[10-May-2021 16:45] 127.0.0.1 POST http /insere_arquivo/arquivo.txt? 5xx INTERNAL SERVER ERROR
Traceback (most recent call last):
  File "/Users/rmj/webdev/BackEnd/flask_api_updown_auth/venv/lib/python3.7/site-packages/flask/app.py", line 1950, in full_dispatch_request
    rv = self.dispatch_request()
  File "/Users/rmj/webdev/BackEnd/flask_api_updown_auth/venv/lib/python3.7/site-packages/flask/app.py", line 1936, in dispatch_request
    return self.view_functions[rule.endpoint](**req.view_args)
  File "/Users/rmj/webdev/BackEnd/flask_api_updown_auth/apiupdown/__init__.py", line 126, in insere_arquivo
    lote = int(linhas[0][37:45])
ValueError: invalid literal for int() with base 10: 'LOTE0001'

[10-May-2021 16:45] 127.0.0.1 POST http /insere_arquivo/arquivo.txt? 5xx INTERNAL SERVER ERROR
Traceback (most recent call last):
  File "/Users/rmj/webdev/BackEnd/flask_api_updown_auth/venv/lib/python3.7/site-packages/flask/app.py", line 1950, in full_dispatch_request
    rv = self.dispatch_request()
  File "/Users/rmj/webdev/BackEnd/flask_api_updown_auth/venv/lib/python3.7/site-packages/flask/app.py", line 1936, in dispatch_request
    return self.view_functions[rule.endpoint](**req.view_args)
  File "/Users/rmj/webdev/BackEnd/flask_api_updown_auth/apiupdown/__init__.py", line 126, in insere_arquivo
    lote = int(linhas[0][37:45])
ValueError: invalid literal for int() with base 10: 'LOTE0001'

[10-May-2021 16:46] 127.0.0.1 POST http /insere_arquivo/arquivo.txt? 201 CREATED b'{\n  "msg": "Adicionados 10 do LOTE0001.", \n  "success": true\n}\n'
[10-May-2021 16:46] 127.0.0.1 POST http /insere_arquivo/arquivo.txt? 201 CREATED b'{\n  "msg": "Adicionados 10 cartoes do LOTE0001.", \n  "success": true\n}\n'
[10-May-2021 16:47] 127.0.0.1 POST http /insere_arquivo/arquivo.txt? 201 CREATED b'{\n  "msg": "Adicionados 10 cartoes do LOTE0001.", \n  "success": true\n}\n'
[10-May-2021 16:49] 127.0.0.1 POST http /insere_arquivo/arquivo.txt? 201 CREATED b'{\n  "msg": "Adicionados 10 cartoes do LOTE0001.", \n  "success": true\n}\n'
[10-May-2021 16:52] 127.0.0.1 POST http /insere_arquivo/arquivo.txt? 201 CREATED b'{\n  "msg": "Adicionados 10 cartoes do LOTE0001.", \n  "success": true\n}\n'
[10-May-2021 16:53] 127.0.0.1 GET http /consulta/445689799999999? 400 BAD REQUEST b'{\n  "msg": "Cartao nao encontrado na base", \n  "success": false\n}\n'
[10-May-2021 16:53] 127.0.0.1 GET http /consulta/4456897999999999? 200 OK b'{\n  "id": "44", \n  "success": true\n}\n'
[10-May-2021 16:53] 127.0.0.1 POST http /insere_linha/C2     4456897999999999? 201 CREATED b'{\n  "msg": "Inserido: \'C\'-\'2\'-\'4456897999999999\'", \n  "success": true\n}\n'
[10-May-2021 16:53] 127.0.0.1 POST http /insere_arquivo/arquivo.txt? 201 CREATED b'{\n  "msg": "Adicionados 10 cartoes do LOTE0001.", \n  "success": true\n}\n'
[10-May-2021 16:54] 127.0.0.1 POST http /insere_arquivo/arquivo.txt? 201 CREATED b'{\n  "msg": "Adicionados 10 cartoes do LOTE0001.", \n  "success": true\n}\n'
[10-May-2021 16:55] 127.0.0.1 GET http /insere_linha/C2     4456897999999999? 5xx INTERNAL SERVER ERROR
Traceback (most recent call last):
  File "/Users/rmj/webdev/BackEnd/flask_api_updown_auth/venv/lib/python3.7/site-packages/flask/app.py", line 1950, in full_dispatch_request
    rv = self.dispatch_request()
  File "/Users/rmj/webdev/BackEnd/flask_api_updown_auth/venv/lib/python3.7/site-packages/flask/app.py", line 1926, in dispatch_request
    self.raise_routing_exception(req)
  File "/Users/rmj/webdev/BackEnd/flask_api_updown_auth/venv/lib/python3.7/site-packages/flask/app.py", line 1908, in raise_routing_exception
    raise request.routing_exception
  File "/Users/rmj/webdev/BackEnd/flask_api_updown_auth/venv/lib/python3.7/site-packages/flask/ctx.py", line 350, in match_request
    result = self.url_adapter.match(return_rule=True)
  File "/Users/rmj/webdev/BackEnd/flask_api_updown_auth/venv/lib/python3.7/site-packages/werkzeug/routing.py", line 1940, in match
    raise MethodNotAllowed(valid_methods=list(have_match_for))
werkzeug.exceptions.MethodNotAllowed: 405 Method Not Allowed: The method is not allowed for the requested URL.

[10-May-2021 16:55] 127.0.0.1 GET http /insere_linha/C2     4456897999999999? 200 OK b'{\n  "msg": "Ocorreu um erro", \n  "success": false\n}\n'
[10-May-2021 16:55] 127.0.0.1 GET http /insere_linha/C2     4456897999999999? 5xx INTERNAL SERVER ERROR
Traceback (most recent call last):
  File "/Users/rmj/webdev/BackEnd/flask_api_updown_auth/venv/lib/python3.7/site-packages/flask/app.py", line 1950, in full_dispatch_request
    rv = self.dispatch_request()
  File "/Users/rmj/webdev/BackEnd/flask_api_updown_auth/venv/lib/python3.7/site-packages/flask/app.py", line 1926, in dispatch_request
    self.raise_routing_exception(req)
  File "/Users/rmj/webdev/BackEnd/flask_api_updown_auth/venv/lib/python3.7/site-packages/flask/app.py", line 1908, in raise_routing_exception
    raise request.routing_exception
  File "/Users/rmj/webdev/BackEnd/flask_api_updown_auth/venv/lib/python3.7/site-packages/flask/ctx.py", line 350, in match_request
    result = self.url_adapter.match(return_rule=True)
  File "/Users/rmj/webdev/BackEnd/flask_api_updown_auth/venv/lib/python3.7/site-packages/werkzeug/routing.py", line 1940, in match
    raise MethodNotAllowed(valid_methods=list(have_match_for))
werkzeug.exceptions.MethodNotAllowed: 405 Method Not Allowed: The method is not allowed for the requested URL.

[10-May-2021 16:55] 127.0.0.1 GET http /insere_linha/C2     4456897999999999? 200 OK b'{\n  "msg": "Ocorreu um erro", \n  "success": false\n}\n'
[10-May-2021 16:55] 127.0.0.1 GET http /insere_linha/C2     4456897999999999? 5xx INTERNAL SERVER ERROR
Traceback (most recent call last):
  File "/Users/rmj/webdev/BackEnd/flask_api_updown_auth/venv/lib/python3.7/site-packages/flask/app.py", line 1950, in full_dispatch_request
    rv = self.dispatch_request()
  File "/Users/rmj/webdev/BackEnd/flask_api_updown_auth/venv/lib/python3.7/site-packages/flask/app.py", line 1926, in dispatch_request
    self.raise_routing_exception(req)
  File "/Users/rmj/webdev/BackEnd/flask_api_updown_auth/venv/lib/python3.7/site-packages/flask/app.py", line 1908, in raise_routing_exception
    raise request.routing_exception
  File "/Users/rmj/webdev/BackEnd/flask_api_updown_auth/venv/lib/python3.7/site-packages/flask/ctx.py", line 350, in match_request
    result = self.url_adapter.match(return_rule=True)
  File "/Users/rmj/webdev/BackEnd/flask_api_updown_auth/venv/lib/python3.7/site-packages/werkzeug/routing.py", line 1940, in match
    raise MethodNotAllowed(valid_methods=list(have_match_for))
werkzeug.exceptions.MethodNotAllowed: 405 Method Not Allowed: The method is not allowed for the requested URL.

[10-May-2021 16:55] 127.0.0.1 GET http /insere_linha/C2     4456897999999999? 200 OK b'{\n  "msg": "Ocorreu um erro", \n  "success": false\n}\n'
[10-May-2021 16:55] 127.0.0.1 GET http /insere_linha/C2     4456897999999999? 5xx INTERNAL SERVER ERROR
Traceback (most recent call last):
  File "/Users/rmj/webdev/BackEnd/flask_api_updown_auth/venv/lib/python3.7/site-packages/flask/app.py", line 1950, in full_dispatch_request
    rv = self.dispatch_request()
  File "/Users/rmj/webdev/BackEnd/flask_api_updown_auth/venv/lib/python3.7/site-packages/flask/app.py", line 1926, in dispatch_request
    self.raise_routing_exception(req)
  File "/Users/rmj/webdev/BackEnd/flask_api_updown_auth/venv/lib/python3.7/site-packages/flask/app.py", line 1908, in raise_routing_exception
    raise request.routing_exception
  File "/Users/rmj/webdev/BackEnd/flask_api_updown_auth/venv/lib/python3.7/site-packages/flask/ctx.py", line 350, in match_request
    result = self.url_adapter.match(return_rule=True)
  File "/Users/rmj/webdev/BackEnd/flask_api_updown_auth/venv/lib/python3.7/site-packages/werkzeug/routing.py", line 1940, in match
    raise MethodNotAllowed(valid_methods=list(have_match_for))
werkzeug.exceptions.MethodNotAllowed: 405 Method Not Allowed: The method is not allowed for the requested URL.

[10-May-2021 16:55] 127.0.0.1 GET http /insere_linha/C2     4456897999999999? 500 INTERNAL SERVER ERROR b'{\n  "msg": "Ocorreu um erro", \n  "success": false\n}\n'
[10-May-2021 16:58] 127.0.0.1 GET http /insere_linha/C2     4456897999999999? 5xx INTERNAL SERVER ERROR
Traceback (most recent call last):
  File "/Users/rmj/webdev/BackEnd/flask_api_updown_auth/venv/lib/python3.7/site-packages/flask/app.py", line 1950, in full_dispatch_request
    rv = self.dispatch_request()
  File "/Users/rmj/webdev/BackEnd/flask_api_updown_auth/venv/lib/python3.7/site-packages/flask/app.py", line 1926, in dispatch_request
    self.raise_routing_exception(req)
  File "/Users/rmj/webdev/BackEnd/flask_api_updown_auth/venv/lib/python3.7/site-packages/flask/app.py", line 1908, in raise_routing_exception
    raise request.routing_exception
  File "/Users/rmj/webdev/BackEnd/flask_api_updown_auth/venv/lib/python3.7/site-packages/flask/ctx.py", line 350, in match_request
    result = self.url_adapter.match(return_rule=True)
  File "/Users/rmj/webdev/BackEnd/flask_api_updown_auth/venv/lib/python3.7/site-packages/werkzeug/routing.py", line 1940, in match
    raise MethodNotAllowed(valid_methods=list(have_match_for))
werkzeug.exceptions.MethodNotAllowed: 405 Method Not Allowed: The method is not allowed for the requested URL.

[10-May-2021 16:58] 127.0.0.1 GET http /insere_linha/C2     4456897999999999? 500 INTERNAL SERVER ERROR b'{\n  "msg": "Ocorreu um erro", \n  "success": false\n}\n'
[10-May-2021 16:58] 127.0.0.1 POST http /insere_arquivo/arquivo.txt? 201 CREATED b'{\n  "msg": "Adicionados 10 cartoes do LOTE0001.", \n  "success": true\n}\n'
[10-May-2021 16:58] 127.0.0.1 POST http /insere_linha/C2     4456897999999999? 201 CREATED b'{\n  "msg": "Inserido: \'C\'-\'2\'-\'4456897999999999\'", \n  "success": true\n}\n'
[10-May-2021 16:58] 127.0.0.1 GET http /consulta/4456897999999999? 200 OK b'{\n  "id": "44", \n  "success": true\n}\n'
[10-May-2021 19:11] 127.0.0.1 GET http /consulta/4456897999999999? 200 OK b'{\n  "id": "44", \n  "success": true\n}\n'
[10-May-2021 19:11] 127.0.0.1 GET http /consulta/4456897999999999? 200 OK b'{\n  "id": "44", \n  "success": true\n}\n'
[10-May-2021 19:15] 127.0.0.1 GET http /consulta/4456897999999999? 200 OK b'{\n  "id": "44", \n  "success": true\n}\n'
[10-May-2021 19:15] 127.0.0.1 POST http /insere_arquivo/arquivo.txt? 201 CREATED b'{\n  "msg": "Adicionados 10 cartoes do LOTE0001.", \n  "success": true\n}\n'
[10-May-2021 19:16] 127.0.0.1 GET http /insere_linha/C2     4456897999999999? 5xx INTERNAL SERVER ERROR
Traceback (most recent call last):
  File "/Users/rmj/webdev/BackEnd/flask_api_updown_auth/venv/lib/python3.7/site-packages/flask/app.py", line 1950, in full_dispatch_request
    rv = self.dispatch_request()
  File "/Users/rmj/webdev/BackEnd/flask_api_updown_auth/venv/lib/python3.7/site-packages/flask/app.py", line 1926, in dispatch_request
    self.raise_routing_exception(req)
  File "/Users/rmj/webdev/BackEnd/flask_api_updown_auth/venv/lib/python3.7/site-packages/flask/app.py", line 1908, in raise_routing_exception
    raise request.routing_exception
  File "/Users/rmj/webdev/BackEnd/flask_api_updown_auth/venv/lib/python3.7/site-packages/flask/ctx.py", line 350, in match_request
    result = self.url_adapter.match(return_rule=True)
  File "/Users/rmj/webdev/BackEnd/flask_api_updown_auth/venv/lib/python3.7/site-packages/werkzeug/routing.py", line 1940, in match
    raise MethodNotAllowed(valid_methods=list(have_match_for))
werkzeug.exceptions.MethodNotAllowed: 405 Method Not Allowed: The method is not allowed for the requested URL.

[10-May-2021 19:16] 127.0.0.1 GET http /insere_linha/C2     4456897999999999? 500 INTERNAL SERVER ERROR b'{\n  "msg": "Ocorreu um erro", \n  "success": false\n}\n'
[10-May-2021 19:38] 127.0.0.1 GET http /insere_linha/C2     4456897999999999? 5xx INTERNAL SERVER ERROR
Traceback (most recent call last):
  File "/Users/rmj/webdev/BackEnd/flask_api_updown_auth/venv/lib/python3.7/site-packages/flask/app.py", line 1950, in full_dispatch_request
    rv = self.dispatch_request()
  File "/Users/rmj/webdev/BackEnd/flask_api_updown_auth/venv/lib/python3.7/site-packages/flask/app.py", line 1926, in dispatch_request
    self.raise_routing_exception(req)
  File "/Users/rmj/webdev/BackEnd/flask_api_updown_auth/venv/lib/python3.7/site-packages/flask/app.py", line 1908, in raise_routing_exception
    raise request.routing_exception
  File "/Users/rmj/webdev/BackEnd/flask_api_updown_auth/venv/lib/python3.7/site-packages/flask/ctx.py", line 350, in match_request
    result = self.url_adapter.match(return_rule=True)
  File "/Users/rmj/webdev/BackEnd/flask_api_updown_auth/venv/lib/python3.7/site-packages/werkzeug/routing.py", line 1940, in match
    raise MethodNotAllowed(valid_methods=list(have_match_for))
werkzeug.exceptions.MethodNotAllowed: 405 Method Not Allowed: The method is not allowed for the requested URL.

[10-May-2021 19:38] 127.0.0.1 GET http /insere_linha/C2     4456897999999999? 500 INTERNAL SERVER ERROR b'{\n  "msg": "Ocorreu um erro", \n  "success": false\n}\n'
[10-May-2021 19:38] 127.0.0.1 GET http /insere_linha/C2     445689799999999? 5xx INTERNAL SERVER ERROR
Traceback (most recent call last):
  File "/Users/rmj/webdev/BackEnd/flask_api_updown_auth/venv/lib/python3.7/site-packages/flask/app.py", line 1950, in full_dispatch_request
    rv = self.dispatch_request()
  File "/Users/rmj/webdev/BackEnd/flask_api_updown_auth/venv/lib/python3.7/site-packages/flask/app.py", line 1926, in dispatch_request
    self.raise_routing_exception(req)
  File "/Users/rmj/webdev/BackEnd/flask_api_updown_auth/venv/lib/python3.7/site-packages/flask/app.py", line 1908, in raise_routing_exception
    raise request.routing_exception
  File "/Users/rmj/webdev/BackEnd/flask_api_updown_auth/venv/lib/python3.7/site-packages/flask/ctx.py", line 350, in match_request
    result = self.url_adapter.match(return_rule=True)
  File "/Users/rmj/webdev/BackEnd/flask_api_updown_auth/venv/lib/python3.7/site-packages/werkzeug/routing.py", line 1940, in match
    raise MethodNotAllowed(valid_methods=list(have_match_for))
werkzeug.exceptions.MethodNotAllowed: 405 Method Not Allowed: The method is not allowed for the requested URL.

[10-May-2021 19:38] 127.0.0.1 GET http /insere_linha/C2     445689799999999? 500 INTERNAL SERVER ERROR b'{\n  "msg": "Ocorreu um erro", \n  "success": false\n}\n'
[10-May-2021 19:38] 127.0.0.1 POST http /insere_linha/C2     4456897999999999? 201 CREATED b'{\n  "msg": "Inserido: \'C\'-\'2\'-\'4456897999999999\'", \n  "success": true\n}\n'
[10-May-2021 19:42] 127.0.0.1 GET http /consulta/4456897999999999? 200 OK b'{\n  "id": "44", \n  "success": true\n}\n'
[10-May-2021 19:42] 127.0.0.1 GET http /consulta/C2     4456897999999999? 400 BAD REQUEST b'{\n  "msg": "Cartao nao encontrado na base", \n  "success": false\n}\n'
[10-May-2021 19:42] 127.0.0.1 GET http /consulta/4456897999999999? 200 OK b'{\n  "id": "44", \n  "success": true\n}\n'
[10-May-2021 19:46] 127.0.0.1 GET http /consulta/44568979999999990? 400 BAD REQUEST b'{\n  "msg": "Cartao nao encontrado na base", \n  "success": false\n}\n'
[10-May-2021 19:47] 127.0.0.1 GET http /consulta/44568979999999990? 400 BAD REQUEST b'{\n  "msg": "Cartao nao encontrado na base", \n  "success": false\n}\n'
[10-May-2021 20:02] 127.0.0.1 GET http /insere_linha/C2     445689799999999? 5xx INTERNAL SERVER ERROR
Traceback (most recent call last):
  File "/Users/rmj/webdev/BackEnd/flask_api_updown_auth/venv/lib/python3.7/site-packages/flask/app.py", line 1950, in full_dispatch_request
    rv = self.dispatch_request()
  File "/Users/rmj/webdev/BackEnd/flask_api_updown_auth/venv/lib/python3.7/site-packages/flask/app.py", line 1926, in dispatch_request
    self.raise_routing_exception(req)
  File "/Users/rmj/webdev/BackEnd/flask_api_updown_auth/venv/lib/python3.7/site-packages/flask/app.py", line 1908, in raise_routing_exception
    raise request.routing_exception
  File "/Users/rmj/webdev/BackEnd/flask_api_updown_auth/venv/lib/python3.7/site-packages/flask/ctx.py", line 350, in match_request
    result = self.url_adapter.match(return_rule=True)
  File "/Users/rmj/webdev/BackEnd/flask_api_updown_auth/venv/lib/python3.7/site-packages/werkzeug/routing.py", line 1940, in match
    raise MethodNotAllowed(valid_methods=list(have_match_for))
werkzeug.exceptions.MethodNotAllowed: 405 Method Not Allowed: The method is not allowed for the requested URL.

[10-May-2021 20:02] 127.0.0.1 GET http /insere_linha/C2     445689799999999? 500 INTERNAL SERVER ERROR b'{\n  "msg": "Ocorreu um erro", \n  "success": false\n}\n'
[10-May-2021 20:13] 127.0.0.1 POST http /insere_arquivo/arquivo.txt? 201 CREATED b'{\n  "msg": "Adicionados 10 cartoes do LOTE0001.", \n  "success": true\n}\n'
[10-May-2021 20:58] 127.0.0.1 POST http /auth? 5xx INTERNAL SERVER ERROR
Traceback (most recent call last):
  File "/Users/rmj/webdev/BackEnd/flask_api_updown_auth/venv/lib/python3.7/site-packages/flask/app.py", line 1950, in full_dispatch_request
    rv = self.dispatch_request()
  File "/Users/rmj/webdev/BackEnd/flask_api_updown_auth/venv/lib/python3.7/site-packages/flask/app.py", line 1936, in dispatch_request
    return self.view_functions[rule.endpoint](**req.view_args)
  File "/Users/rmj/webdev/BackEnd/flask_api_updown_auth/venv/lib/python3.7/site-packages/flask_jwt/__init__.py", line 115, in _default_auth_request_handler
    username = data.get(current_app.config.get('JWT_AUTH_USERNAME_KEY'), None)
AttributeError: 'NoneType' object has no attribute 'get'

[10-May-2021 20:58] 127.0.0.1 POST http /auth? 500 INTERNAL SERVER ERROR b'{\n  "msg": "Ocorreu um erro", \n  "success": false\n}\n'
[10-May-2021 20:58] 127.0.0.1 POST http /auth? 5xx INTERNAL SERVER ERROR
Traceback (most recent call last):
  File "/Users/rmj/webdev/BackEnd/flask_api_updown_auth/venv/lib/python3.7/site-packages/flask/app.py", line 1950, in full_dispatch_request
    rv = self.dispatch_request()
  File "/Users/rmj/webdev/BackEnd/flask_api_updown_auth/venv/lib/python3.7/site-packages/flask/app.py", line 1936, in dispatch_request
    return self.view_functions[rule.endpoint](**req.view_args)
  File "/Users/rmj/webdev/BackEnd/flask_api_updown_auth/venv/lib/python3.7/site-packages/flask_jwt/__init__.py", line 115, in _default_auth_request_handler
    username = data.get(current_app.config.get('JWT_AUTH_USERNAME_KEY'), None)
AttributeError: 'NoneType' object has no attribute 'get'

[10-May-2021 20:58] 127.0.0.1 POST http /auth? 500 INTERNAL SERVER ERROR b'{\n  "msg": "Ocorreu um erro", \n  "success": false\n}\n'
[10-May-2021 20:59] 127.0.0.1 POST http /auth? 5xx INTERNAL SERVER ERROR
Traceback (most recent call last):
  File "/Users/rmj/webdev/BackEnd/flask_api_updown_auth/venv/lib/python3.7/site-packages/werkzeug/wrappers/json.py", line 119, in get_json
    rv = self.json_module.loads(data)
  File "/Users/rmj/webdev/BackEnd/flask_api_updown_auth/venv/lib/python3.7/site-packages/flask/json/__init__.py", line 253, in loads
    return _json.loads(s, **kwargs)
  File "/Library/Frameworks/Python.framework/Versions/3.7/lib/python3.7/json/__init__.py", line 361, in loads
    return cls(**kw).decode(s)
  File "/Library/Frameworks/Python.framework/Versions/3.7/lib/python3.7/json/decoder.py", line 337, in decode
    obj, end = self.raw_decode(s, idx=_w(s, 0).end())
  File "/Library/Frameworks/Python.framework/Versions/3.7/lib/python3.7/json/decoder.py", line 353, in raw_decode
    obj, end = self.scan_once(s, idx)
json.decoder.JSONDecodeError: Expecting property name enclosed in double quotes: line 2 column 2 (char 3)

During handling of the above exception, another exception occurred:

Traceback (most recent call last):
  File "/Users/rmj/webdev/BackEnd/flask_api_updown_auth/venv/lib/python3.7/site-packages/flask/app.py", line 1950, in full_dispatch_request
    rv = self.dispatch_request()
  File "/Users/rmj/webdev/BackEnd/flask_api_updown_auth/venv/lib/python3.7/site-packages/flask/app.py", line 1936, in dispatch_request
    return self.view_functions[rule.endpoint](**req.view_args)
  File "/Users/rmj/webdev/BackEnd/flask_api_updown_auth/venv/lib/python3.7/site-packages/flask_jwt/__init__.py", line 114, in _default_auth_request_handler
    data = request.get_json()
  File "/Users/rmj/webdev/BackEnd/flask_api_updown_auth/venv/lib/python3.7/site-packages/werkzeug/wrappers/json.py", line 128, in get_json
    rv = self.on_json_loading_failed(e)
  File "/Users/rmj/webdev/BackEnd/flask_api_updown_auth/venv/lib/python3.7/site-packages/flask/wrappers.py", line 25, in on_json_loading_failed
    raise BadRequest("Failed to decode JSON object: {0}".format(e))
werkzeug.exceptions.BadRequest: 400 Bad Request: Failed to decode JSON object: Expecting property name enclosed in double quotes: line 2 column 2 (char 3)

[10-May-2021 20:59] 127.0.0.1 POST http /auth? 500 INTERNAL SERVER ERROR b'{\n  "msg": "Ocorreu um erro", \n  "success": false\n}\n'
[10-May-2021 20:59] 127.0.0.1 POST http /auth? 5xx INTERNAL SERVER ERROR
Traceback (most recent call last):
  File "/Users/rmj/webdev/BackEnd/flask_api_updown_auth/venv/lib/python3.7/site-packages/werkzeug/wrappers/json.py", line 119, in get_json
    rv = self.json_module.loads(data)
  File "/Users/rmj/webdev/BackEnd/flask_api_updown_auth/venv/lib/python3.7/site-packages/flask/json/__init__.py", line 253, in loads
    return _json.loads(s, **kwargs)
  File "/Library/Frameworks/Python.framework/Versions/3.7/lib/python3.7/json/__init__.py", line 361, in loads
    return cls(**kw).decode(s)
  File "/Library/Frameworks/Python.framework/Versions/3.7/lib/python3.7/json/decoder.py", line 337, in decode
    obj, end = self.raw_decode(s, idx=_w(s, 0).end())
  File "/Library/Frameworks/Python.framework/Versions/3.7/lib/python3.7/json/decoder.py", line 353, in raw_decode
    obj, end = self.scan_once(s, idx)
json.decoder.JSONDecodeError: Expecting property name enclosed in double quotes: line 2 column 2 (char 3)

During handling of the above exception, another exception occurred:

Traceback (most recent call last):
  File "/Users/rmj/webdev/BackEnd/flask_api_updown_auth/venv/lib/python3.7/site-packages/flask/app.py", line 1950, in full_dispatch_request
    rv = self.dispatch_request()
  File "/Users/rmj/webdev/BackEnd/flask_api_updown_auth/venv/lib/python3.7/site-packages/flask/app.py", line 1936, in dispatch_request
    return self.view_functions[rule.endpoint](**req.view_args)
  File "/Users/rmj/webdev/BackEnd/flask_api_updown_auth/venv/lib/python3.7/site-packages/flask_jwt/__init__.py", line 114, in _default_auth_request_handler
    data = request.get_json()
  File "/Users/rmj/webdev/BackEnd/flask_api_updown_auth/venv/lib/python3.7/site-packages/werkzeug/wrappers/json.py", line 128, in get_json
    rv = self.on_json_loading_failed(e)
  File "/Users/rmj/webdev/BackEnd/flask_api_updown_auth/venv/lib/python3.7/site-packages/flask/wrappers.py", line 25, in on_json_loading_failed
    raise BadRequest("Failed to decode JSON object: {0}".format(e))
werkzeug.exceptions.BadRequest: 400 Bad Request: Failed to decode JSON object: Expecting property name enclosed in double quotes: line 2 column 2 (char 3)

[10-May-2021 20:59] 127.0.0.1 POST http /auth? 500 INTERNAL SERVER ERROR b'{\n  "msg": "Ocorreu um erro", \n  "success": false\n}\n'
[10-May-2021 21:00] 127.0.0.1 POST http /auth? 200 OK b'{\n  "access_token": "eyJ0eXAiOiJKV1QiLCJhbGciOiJIUzI1NiJ9.eyJleHAiOjE2MjA2OTE1MjAsImlhdCI6MTYyMDY5MTIyMCwibmJmIjoxNjIwNjkxMjIwLCJpZGVudGl0eSI6MX0.FmNUWGUbZB1fZbkFYLqV9aPCkLasQC3Aut4nRyyHUZc"\n}\n'
[10-May-2021 21:12] 127.0.0.1 POST http /auth? 200 OK b'{\n  "access_token": "eyJ0eXAiOiJKV1QiLCJhbGciOiJIUzI1NiJ9.eyJleHAiOjE2MjA2OTIyNDgsImlhdCI6MTYyMDY5MTk0OCwibmJmIjoxNjIwNjkxOTQ4LCJpZGVudGl0eSI6MX0.SiUhq4P939Wlai8xZ7IYgiuE6tdJ322_dMHSAvEuoto"\n}\n'
[10-May-2021 21:23] 127.0.0.1 GET http /consulta/44568979999999990? 401 UNAUTHORIZED b'{\n  "description": "Unsupported authorization type", \n  "error": "Invalid JWT header", \n  "status_code": 401\n}\n'
[10-May-2021 21:23] 127.0.0.1 GET http /consulta/44568979999999990? 401 UNAUTHORIZED b'{\n  "description": "Unsupported authorization type", \n  "error": "Invalid JWT header", \n  "status_code": 401\n}\n'
[10-May-2021 21:26] 127.0.0.1 GET http /consulta/44568979999999990? 401 UNAUTHORIZED b'{\n  "description": "Unsupported authorization type", \n  "error": "Invalid JWT header", \n  "status_code": 401\n}\n'
[10-May-2021 21:27] 127.0.0.1 POST http /auth? 200 OK b'{\n  "access_token": "eyJ0eXAiOiJKV1QiLCJhbGciOiJIUzI1NiJ9.eyJleHAiOjE2MjA2OTMxNTksImlhdCI6MTYyMDY5Mjg1OSwibmJmIjoxNjIwNjkyODU5LCJpZGVudGl0eSI6MX0.0hC_WeyqF-c23a3uS8fsOmgcEiI2W-l4INLX5ORBmco"\n}\n'
[10-May-2021 21:27] 127.0.0.1 GET http /consulta/44568979999999990? 401 UNAUTHORIZED b'{\n  "description": "Unsupported authorization type", \n  "error": "Invalid JWT header", \n  "status_code": 401\n}\n'
[10-May-2021 21:28] 127.0.0.1 GET http /consulta/44568979999999990? 400 BAD REQUEST b'{\n  "msg": "Cartao nao encontrado na base", \n  "success": false\n}\n'
[10-May-2021 21:44] 127.0.0.1 GET http /consulta/44568979999999990? 401 UNAUTHORIZED b'{\n  "description": "Invalid crypto padding", \n  "error": "Invalid token", \n  "status_code": 401\n}\n'
[10-May-2021 21:45] 127.0.0.1 POST http /auth? 200 OK b'{\n  "access_token": "eyJ0eXAiOiJKV1QiLCJhbGciOiJIUzI1NiJ9.eyJleHAiOjE2MjA2OTQyMzEsImlhdCI6MTYyMDY5MzkzMSwibmJmIjoxNjIwNjkzOTMxLCJpZGVudGl0eSI6Mn0.AehSVCvGnGvywJObnSXYem3Pbi98q6cekRId1fNn9pA"\n}\n'
[10-May-2021 21:45] 127.0.0.1 POST http /auth? 401 UNAUTHORIZED b'{\n  "description": "Invalid credentials", \n  "error": "Bad Request", \n  "status_code": 401\n}\n'
